caloba23
caloba23
Cloning into 'orchestra'...
==========================================================
setup root...
==========================================================
setup root...
==========================================================
==========================================================
setup orchestra...
==========================================================
Traceback (most recent call last):
  File "/usr/local/lib/python3.6/dist-packages/sqlalchemy/engine/base.py", line 3250, in _wrap_pool_connect
    return fn()
  File "/usr/local/lib/python3.6/dist-packages/sqlalchemy/pool/base.py", line 310, in connect
    return _ConnectionFairy._checkout(self)
  File "/usr/local/lib/python3.6/dist-packages/sqlalchemy/pool/base.py", line 868, in _checkout
    fairy = _ConnectionRecord.checkout(pool)
  File "/usr/local/lib/python3.6/dist-packages/sqlalchemy/pool/base.py", line 476, in checkout
    rec = pool._do_get()
  File "/usr/local/lib/python3.6/dist-packages/sqlalchemy/pool/impl.py", line 146, in _do_get
    self._dec_overflow()
  File "/usr/local/lib/python3.6/dist-packages/sqlalchemy/util/langhelpers.py", line 72, in __exit__
    with_traceback=exc_tb,
  File "/usr/local/lib/python3.6/dist-packages/sqlalchemy/util/compat.py", line 207, in raise_
    raise exception
  File "/usr/local/lib/python3.6/dist-packages/sqlalchemy/pool/impl.py", line 143, in _do_get
    return self._create_connection()
  File "/usr/local/lib/python3.6/dist-packages/sqlalchemy/pool/base.py", line 256, in _create_connection
    return _ConnectionRecord(self)
  File "/usr/local/lib/python3.6/dist-packages/sqlalchemy/pool/base.py", line 371, in __init__
    self.__connect()
  File "/usr/local/lib/python3.6/dist-packages/sqlalchemy/pool/base.py", line 666, in __connect
    pool.logger.debug("Error on connect(): %s", e)
  File "/usr/local/lib/python3.6/dist-packages/sqlalchemy/util/langhelpers.py", line 72, in __exit__
    with_traceback=exc_tb,
  File "/usr/local/lib/python3.6/dist-packages/sqlalchemy/util/compat.py", line 207, in raise_
    raise exception
  File "/usr/local/lib/python3.6/dist-packages/sqlalchemy/pool/base.py", line 661, in __connect
    self.dbapi_connection = connection = pool._invoke_creator(self)
  File "/usr/local/lib/python3.6/dist-packages/sqlalchemy/engine/create.py", line 590, in connect
    return dialect.connect(*cargs, **cparams)
  File "/usr/local/lib/python3.6/dist-packages/sqlalchemy/engine/default.py", line 597, in connect
    return self.dbapi.connect(*cargs, **cparams)
  File "/usr/local/lib/python3.6/dist-packages/psycopg2/__init__.py", line 122, in connect
    conn = _connect(dsn, connection_factory=connection_factory, **kwasync)
psycopg2.OperationalError: connection to server at "localhost" (::1), port 5432 failed: Connection refused
	Is the server running on that host and accepting TCP/IP connections?
connection to server at "localhost" (127.0.0.1), port 5432 failed: Connection refused
	Is the server running on that host and accepting TCP/IP connections?


The above exception was the direct cause of the following exception:

Traceback (most recent call last):
  File "/tmp/tmp.d9lusb0FGf/orchestra/orchestra/parsers/PilotParser.py", line 73, in run
    pilot.init()
  File "/tmp/tmp.d9lusb0FGf/orchestra/orchestra/Pilot.py", line 54, in init
    self.__devices.init()
  File "/tmp/tmp.d9lusb0FGf/orchestra/orchestra/core/Devices.py", line 34, in init
    for device in self.__db.session().query(Device).filter(Device.nodename==self.nodename).all():
  File "/usr/local/lib/python3.6/dist-packages/sqlalchemy/orm/query.py", line 2759, in all
    return self._iter().all()
  File "/usr/local/lib/python3.6/dist-packages/sqlalchemy/orm/query.py", line 2897, in _iter
    execution_options={"_sa_orm_load_options": self.load_options},
  File "/usr/local/lib/python3.6/dist-packages/sqlalchemy/orm/session.py", line 1691, in execute
    conn = self._connection_for_bind(bind)
  File "/usr/local/lib/python3.6/dist-packages/sqlalchemy/orm/session.py", line 1533, in _connection_for_bind
    engine, execution_options
  File "/usr/local/lib/python3.6/dist-packages/sqlalchemy/orm/session.py", line 747, in _connection_for_bind
    conn = bind.connect()
  File "/usr/local/lib/python3.6/dist-packages/sqlalchemy/engine/base.py", line 3204, in connect
    return self._connection_cls(self, close_with_result=close_with_result)
  File "/usr/local/lib/python3.6/dist-packages/sqlalchemy/engine/base.py", line 96, in __init__
    else engine.raw_connection()
  File "/usr/local/lib/python3.6/dist-packages/sqlalchemy/engine/base.py", line 3283, in raw_connection
    return self._wrap_pool_connect(self.pool.connect, _connection)
  File "/usr/local/lib/python3.6/dist-packages/sqlalchemy/engine/base.py", line 3254, in _wrap_pool_connect
    e, dialect, self
  File "/usr/local/lib/python3.6/dist-packages/sqlalchemy/engine/base.py", line 2101, in _handle_dbapi_exception_noconnection
    sqlalchemy_exception, with_traceback=exc_info[2], from_=e
  File "/usr/local/lib/python3.6/dist-packages/sqlalchemy/util/compat.py", line 207, in raise_
    raise exception
  File "/usr/local/lib/python3.6/dist-packages/sqlalchemy/engine/base.py", line 3250, in _wrap_pool_connect
    return fn()
  File "/usr/local/lib/python3.6/dist-packages/sqlalchemy/pool/base.py", line 310, in connect
    return _ConnectionFairy._checkout(self)
  File "/usr/local/lib/python3.6/dist-packages/sqlalchemy/pool/base.py", line 868, in _checkout
    fairy = _ConnectionRecord.checkout(pool)
  File "/usr/local/lib/python3.6/dist-packages/sqlalchemy/pool/base.py", line 476, in checkout
    rec = pool._do_get()
  File "/usr/local/lib/python3.6/dist-packages/sqlalchemy/pool/impl.py", line 146, in _do_get
    self._dec_overflow()
  File "/usr/local/lib/python3.6/dist-packages/sqlalchemy/util/langhelpers.py", line 72, in __exit__
    with_traceback=exc_tb,
  File "/usr/local/lib/python3.6/dist-packages/sqlalchemy/util/compat.py", line 207, in raise_
    raise exception
  File "/usr/local/lib/python3.6/dist-packages/sqlalchemy/pool/impl.py", line 143, in _do_get
    return self._create_connection()
  File "/usr/local/lib/python3.6/dist-packages/sqlalchemy/pool/base.py", line 256, in _create_connection
    return _ConnectionRecord(self)
  File "/usr/local/lib/python3.6/dist-packages/sqlalchemy/pool/base.py", line 371, in __init__
    self.__connect()
  File "/usr/local/lib/python3.6/dist-packages/sqlalchemy/pool/base.py", line 666, in __connect
    pool.logger.debug("Error on connect(): %s", e)
  File "/usr/local/lib/python3.6/dist-packages/sqlalchemy/util/langhelpers.py", line 72, in __exit__
    with_traceback=exc_tb,
  File "/usr/local/lib/python3.6/dist-packages/sqlalchemy/util/compat.py", line 207, in raise_
    raise exception
  File "/usr/local/lib/python3.6/dist-packages/sqlalchemy/pool/base.py", line 661, in __connect
    self.dbapi_connection = connection = pool._invoke_creator(self)
  File "/usr/local/lib/python3.6/dist-packages/sqlalchemy/engine/create.py", line 590, in connect
    return dialect.connect(*cargs, **cparams)
  File "/usr/local/lib/python3.6/dist-packages/sqlalchemy/engine/default.py", line 597, in connect
    return self.dbapi.connect(*cargs, **cparams)
  File "/usr/local/lib/python3.6/dist-packages/psycopg2/__init__.py", line 122, in connect
    conn = _connect(dsn, connection_factory=connection_factory, **kwasync)
sqlalchemy.exc.OperationalError: (psycopg2.OperationalError) connection to server at "localhost" (::1), port 5432 failed: Connection refused
	Is the server running on that host and accepting TCP/IP connections?
connection to server at "localhost" (127.0.0.1), port 5432 failed: Connection refused
	Is the server running on that host and accepting TCP/IP connections?

(Background on this error at: https://sqlalche.me/e/14/e3q8)
Traceback (most recent call last):
  File "/usr/local/lib/python3.6/dist-packages/sqlalchemy/engine/base.py", line 3250, in _wrap_pool_connect
    return fn()
  File "/usr/local/lib/python3.6/dist-packages/sqlalchemy/pool/base.py", line 310, in connect
    return _ConnectionFairy._checkout(self)
  File "/usr/local/lib/python3.6/dist-packages/sqlalchemy/pool/base.py", line 868, in _checkout
    fairy = _ConnectionRecord.checkout(pool)
  File "/usr/local/lib/python3.6/dist-packages/sqlalchemy/pool/base.py", line 476, in checkout
    rec = pool._do_get()
  File "/usr/local/lib/python3.6/dist-packages/sqlalchemy/pool/impl.py", line 146, in _do_get
    self._dec_overflow()
  File "/usr/local/lib/python3.6/dist-packages/sqlalchemy/util/langhelpers.py", line 72, in __exit__
    with_traceback=exc_tb,
  File "/usr/local/lib/python3.6/dist-packages/sqlalchemy/util/compat.py", line 207, in raise_
    raise exception
  File "/usr/local/lib/python3.6/dist-packages/sqlalchemy/pool/impl.py", line 143, in _do_get
    return self._create_connection()
  File "/usr/local/lib/python3.6/dist-packages/sqlalchemy/pool/base.py", line 256, in _create_connection
    return _ConnectionRecord(self)
  File "/usr/local/lib/python3.6/dist-packages/sqlalchemy/pool/base.py", line 371, in __init__
    self.__connect()
  File "/usr/local/lib/python3.6/dist-packages/sqlalchemy/pool/base.py", line 666, in __connect
    pool.logger.debug("Error on connect(): %s", e)
  File "/usr/local/lib/python3.6/dist-packages/sqlalchemy/util/langhelpers.py", line 72, in __exit__
    with_traceback=exc_tb,
  File "/usr/local/lib/python3.6/dist-packages/sqlalchemy/util/compat.py", line 207, in raise_
    raise exception
  File "/usr/local/lib/python3.6/dist-packages/sqlalchemy/pool/base.py", line 661, in __connect
    self.dbapi_connection = connection = pool._invoke_creator(self)
  File "/usr/local/lib/python3.6/dist-packages/sqlalchemy/engine/create.py", line 590, in connect
    return dialect.connect(*cargs, **cparams)
  File "/usr/local/lib/python3.6/dist-packages/sqlalchemy/engine/default.py", line 597, in connect
    return self.dbapi.connect(*cargs, **cparams)
  File "/usr/local/lib/python3.6/dist-packages/psycopg2/__init__.py", line 122, in connect
    conn = _connect(dsn, connection_factory=connection_factory, **kwasync)
psycopg2.OperationalError: connection to server at "localhost" (::1), port 5432 failed: Connection refused
	Is the server running on that host and accepting TCP/IP connections?
connection to server at "localhost" (127.0.0.1), port 5432 failed: Connection refused
	Is the server running on that host and accepting TCP/IP connections?


The above exception was the direct cause of the following exception:

Traceback (most recent call last):
  File "/tmp/tmp.d9lusb0FGf/orchestra/orchestra/parsers/PilotParser.py", line 73, in run
    pilot.init()
  File "/tmp/tmp.d9lusb0FGf/orchestra/orchestra/Pilot.py", line 54, in init
    self.__devices.init()
  File "/tmp/tmp.d9lusb0FGf/orchestra/orchestra/core/Devices.py", line 34, in init
    for device in self.__db.session().query(Device).filter(Device.nodename==self.nodename).all():
  File "/usr/local/lib/python3.6/dist-packages/sqlalchemy/orm/query.py", line 2759, in all
    return self._iter().all()
  File "/usr/local/lib/python3.6/dist-packages/sqlalchemy/orm/query.py", line 2897, in _iter
    execution_options={"_sa_orm_load_options": self.load_options},
  File "/usr/local/lib/python3.6/dist-packages/sqlalchemy/orm/session.py", line 1691, in execute
    conn = self._connection_for_bind(bind)
  File "/usr/local/lib/python3.6/dist-packages/sqlalchemy/orm/session.py", line 1533, in _connection_for_bind
    engine, execution_options
  File "/usr/local/lib/python3.6/dist-packages/sqlalchemy/orm/session.py", line 747, in _connection_for_bind
    conn = bind.connect()
  File "/usr/local/lib/python3.6/dist-packages/sqlalchemy/engine/base.py", line 3204, in connect
    return self._connection_cls(self, close_with_result=close_with_result)
  File "/usr/local/lib/python3.6/dist-packages/sqlalchemy/engine/base.py", line 96, in __init__
    else engine.raw_connection()
  File "/usr/local/lib/python3.6/dist-packages/sqlalchemy/engine/base.py", line 3283, in raw_connection
    return self._wrap_pool_connect(self.pool.connect, _connection)
  File "/usr/local/lib/python3.6/dist-packages/sqlalchemy/engine/base.py", line 3254, in _wrap_pool_connect
    e, dialect, self
  File "/usr/local/lib/python3.6/dist-packages/sqlalchemy/engine/base.py", line 2101, in _handle_dbapi_exception_noconnection
    sqlalchemy_exception, with_traceback=exc_info[2], from_=e
  File "/usr/local/lib/python3.6/dist-packages/sqlalchemy/util/compat.py", line 207, in raise_
    raise exception
  File "/usr/local/lib/python3.6/dist-packages/sqlalchemy/engine/base.py", line 3250, in _wrap_pool_connect
    return fn()
  File "/usr/local/lib/python3.6/dist-packages/sqlalchemy/pool/base.py", line 310, in connect
    return _ConnectionFairy._checkout(self)
  File "/usr/local/lib/python3.6/dist-packages/sqlalchemy/pool/base.py", line 868, in _checkout
    fairy = _ConnectionRecord.checkout(pool)
  File "/usr/local/lib/python3.6/dist-packages/sqlalchemy/pool/base.py", line 476, in checkout
    rec = pool._do_get()
  File "/usr/local/lib/python3.6/dist-packages/sqlalchemy/pool/impl.py", line 146, in _do_get
    self._dec_overflow()
  File "/usr/local/lib/python3.6/dist-packages/sqlalchemy/util/langhelpers.py", line 72, in __exit__
    with_traceback=exc_tb,
  File "/usr/local/lib/python3.6/dist-packages/sqlalchemy/util/compat.py", line 207, in raise_
    raise exception
  File "/usr/local/lib/python3.6/dist-packages/sqlalchemy/pool/impl.py", line 143, in _do_get
    return self._create_connection()
  File "/usr/local/lib/python3.6/dist-packages/sqlalchemy/pool/base.py", line 256, in _create_connection
    return _ConnectionRecord(self)
  File "/usr/local/lib/python3.6/dist-packages/sqlalchemy/pool/base.py", line 371, in __init__
    self.__connect()
  File "/usr/local/lib/python3.6/dist-packages/sqlalchemy/pool/base.py", line 666, in __connect
    pool.logger.debug("Error on connect(): %s", e)
  File "/usr/local/lib/python3.6/dist-packages/sqlalchemy/util/langhelpers.py", line 72, in __exit__
    with_traceback=exc_tb,
  File "/usr/local/lib/python3.6/dist-packages/sqlalchemy/util/compat.py", line 207, in raise_
    raise exception
  File "/usr/local/lib/python3.6/dist-packages/sqlalchemy/pool/base.py", line 661, in __connect
    self.dbapi_connection = connection = pool._invoke_creator(self)
  File "/usr/local/lib/python3.6/dist-packages/sqlalchemy/engine/create.py", line 590, in connect
    return dialect.connect(*cargs, **cparams)
  File "/usr/local/lib/python3.6/dist-packages/sqlalchemy/engine/default.py", line 597, in connect
    return self.dbapi.connect(*cargs, **cparams)
  File "/usr/local/lib/python3.6/dist-packages/psycopg2/__init__.py", line 122, in connect
    conn = _connect(dsn, connection_factory=connection_factory, **kwasync)
sqlalchemy.exc.OperationalError: (psycopg2.OperationalError) connection to server at "localhost" (::1), port 5432 failed: Connection refused
	Is the server running on that host and accepting TCP/IP connections?
connection to server at "localhost" (127.0.0.1), port 5432 failed: Connection refused
	Is the server running on that host and accepting TCP/IP connections?

(Background on this error at: https://sqlalche.me/e/14/e3q8)

During handling of the above exception, another exception occurred:

Traceback (most recent call last):
  File "/tmp/tmp.d9lusb0FGf/orchestra/orchestra/mailing/Postman.py", line 45, in __send
    server.login(self.__myEmail, self.__myPassword)
  File "/usr/lib/python3.6/smtplib.py", line 721, in login
    initial_response_ok=initial_response_ok)
  File "/usr/lib/python3.6/smtplib.py", line 631, in auth
    (code, resp) = self.docmd("AUTH", mechanism + " " + response)
  File "/usr/lib/python3.6/smtplib.py", line 421, in docmd
    return self.getreply()
  File "/usr/lib/python3.6/smtplib.py", line 394, in getreply
    raise SMTPServerDisconnected("Connection unexpectedly closed")
smtplib.SMTPServerDisconnected: Connection unexpectedly closed
Traceback (most recent call last):
  File "/usr/local/lib/python3.6/dist-packages/sqlalchemy/engine/base.py", line 3250, in _wrap_pool_connect
    return fn()
  File "/usr/local/lib/python3.6/dist-packages/sqlalchemy/pool/base.py", line 310, in connect
    return _ConnectionFairy._checkout(self)
  File "/usr/local/lib/python3.6/dist-packages/sqlalchemy/pool/base.py", line 868, in _checkout
    fairy = _ConnectionRecord.checkout(pool)
  File "/usr/local/lib/python3.6/dist-packages/sqlalchemy/pool/base.py", line 476, in checkout
    rec = pool._do_get()
  File "/usr/local/lib/python3.6/dist-packages/sqlalchemy/pool/impl.py", line 146, in _do_get
    self._dec_overflow()
  File "/usr/local/lib/python3.6/dist-packages/sqlalchemy/util/langhelpers.py", line 72, in __exit__
    with_traceback=exc_tb,
  File "/usr/local/lib/python3.6/dist-packages/sqlalchemy/util/compat.py", line 207, in raise_
    raise exception
  File "/usr/local/lib/python3.6/dist-packages/sqlalchemy/pool/impl.py", line 143, in _do_get
    return self._create_connection()
  File "/usr/local/lib/python3.6/dist-packages/sqlalchemy/pool/base.py", line 256, in _create_connection
    return _ConnectionRecord(self)
  File "/usr/local/lib/python3.6/dist-packages/sqlalchemy/pool/base.py", line 371, in __init__
    self.__connect()
  File "/usr/local/lib/python3.6/dist-packages/sqlalchemy/pool/base.py", line 666, in __connect
    pool.logger.debug("Error on connect(): %s", e)
  File "/usr/local/lib/python3.6/dist-packages/sqlalchemy/util/langhelpers.py", line 72, in __exit__
    with_traceback=exc_tb,
  File "/usr/local/lib/python3.6/dist-packages/sqlalchemy/util/compat.py", line 207, in raise_
    raise exception
  File "/usr/local/lib/python3.6/dist-packages/sqlalchemy/pool/base.py", line 661, in __connect
    self.dbapi_connection = connection = pool._invoke_creator(self)
  File "/usr/local/lib/python3.6/dist-packages/sqlalchemy/engine/create.py", line 590, in connect
    return dialect.connect(*cargs, **cparams)
  File "/usr/local/lib/python3.6/dist-packages/sqlalchemy/engine/default.py", line 597, in connect
    return self.dbapi.connect(*cargs, **cparams)
  File "/usr/local/lib/python3.6/dist-packages/psycopg2/__init__.py", line 122, in connect
    conn = _connect(dsn, connection_factory=connection_factory, **kwasync)
psycopg2.OperationalError: connection to server at "localhost" (::1), port 5432 failed: Connection refused
	Is the server running on that host and accepting TCP/IP connections?
connection to server at "localhost" (127.0.0.1), port 5432 failed: Connection refused
	Is the server running on that host and accepting TCP/IP connections?


The above exception was the direct cause of the following exception:

Traceback (most recent call last):
  File "/tmp/tmp.d9lusb0FGf/orchestra/orchestra/parsers/PilotParser.py", line 73, in run
    pilot.init()
  File "/tmp/tmp.d9lusb0FGf/orchestra/orchestra/Pilot.py", line 54, in init
    self.__devices.init()
  File "/tmp/tmp.d9lusb0FGf/orchestra/orchestra/core/Devices.py", line 34, in init
    for device in self.__db.session().query(Device).filter(Device.nodename==self.nodename).all():
  File "/usr/local/lib/python3.6/dist-packages/sqlalchemy/orm/query.py", line 2759, in all
    return self._iter().all()
  File "/usr/local/lib/python3.6/dist-packages/sqlalchemy/orm/query.py", line 2897, in _iter
    execution_options={"_sa_orm_load_options": self.load_options},
  File "/usr/local/lib/python3.6/dist-packages/sqlalchemy/orm/session.py", line 1691, in execute
    conn = self._connection_for_bind(bind)
  File "/usr/local/lib/python3.6/dist-packages/sqlalchemy/orm/session.py", line 1533, in _connection_for_bind
    engine, execution_options
  File "/usr/local/lib/python3.6/dist-packages/sqlalchemy/orm/session.py", line 747, in _connection_for_bind
    conn = bind.connect()
  File "/usr/local/lib/python3.6/dist-packages/sqlalchemy/engine/base.py", line 3204, in connect
    return self._connection_cls(self, close_with_result=close_with_result)
  File "/usr/local/lib/python3.6/dist-packages/sqlalchemy/engine/base.py", line 96, in __init__
    else engine.raw_connection()
  File "/usr/local/lib/python3.6/dist-packages/sqlalchemy/engine/base.py", line 3283, in raw_connection
    return self._wrap_pool_connect(self.pool.connect, _connection)
  File "/usr/local/lib/python3.6/dist-packages/sqlalchemy/engine/base.py", line 3254, in _wrap_pool_connect
    e, dialect, self
  File "/usr/local/lib/python3.6/dist-packages/sqlalchemy/engine/base.py", line 2101, in _handle_dbapi_exception_noconnection
    sqlalchemy_exception, with_traceback=exc_info[2], from_=e
  File "/usr/local/lib/python3.6/dist-packages/sqlalchemy/util/compat.py", line 207, in raise_
    raise exception
  File "/usr/local/lib/python3.6/dist-packages/sqlalchemy/engine/base.py", line 3250, in _wrap_pool_connect
    return fn()
  File "/usr/local/lib/python3.6/dist-packages/sqlalchemy/pool/base.py", line 310, in connect
    return _ConnectionFairy._checkout(self)
  File "/usr/local/lib/python3.6/dist-packages/sqlalchemy/pool/base.py", line 868, in _checkout
    fairy = _ConnectionRecord.checkout(pool)
  File "/usr/local/lib/python3.6/dist-packages/sqlalchemy/pool/base.py", line 476, in checkout
    rec = pool._do_get()
  File "/usr/local/lib/python3.6/dist-packages/sqlalchemy/pool/impl.py", line 146, in _do_get
    self._dec_overflow()
  File "/usr/local/lib/python3.6/dist-packages/sqlalchemy/util/langhelpers.py", line 72, in __exit__
    with_traceback=exc_tb,
  File "/usr/local/lib/python3.6/dist-packages/sqlalchemy/util/compat.py", line 207, in raise_
    raise exception
  File "/usr/local/lib/python3.6/dist-packages/sqlalchemy/pool/impl.py", line 143, in _do_get
    return self._create_connection()
  File "/usr/local/lib/python3.6/dist-packages/sqlalchemy/pool/base.py", line 256, in _create_connection
    return _ConnectionRecord(self)
  File "/usr/local/lib/python3.6/dist-packages/sqlalchemy/pool/base.py", line 371, in __init__
    self.__connect()
  File "/usr/local/lib/python3.6/dist-packages/sqlalchemy/pool/base.py", line 666, in __connect
    pool.logger.debug("Error on connect(): %s", e)
  File "/usr/local/lib/python3.6/dist-packages/sqlalchemy/util/langhelpers.py", line 72, in __exit__
    with_traceback=exc_tb,
  File "/usr/local/lib/python3.6/dist-packages/sqlalchemy/util/compat.py", line 207, in raise_
    raise exception
  File "/usr/local/lib/python3.6/dist-packages/sqlalchemy/pool/base.py", line 661, in __connect
    self.dbapi_connection = connection = pool._invoke_creator(self)
  File "/usr/local/lib/python3.6/dist-packages/sqlalchemy/engine/create.py", line 590, in connect
    return dialect.connect(*cargs, **cparams)
  File "/usr/local/lib/python3.6/dist-packages/sqlalchemy/engine/default.py", line 597, in connect
    return self.dbapi.connect(*cargs, **cparams)
  File "/usr/local/lib/python3.6/dist-packages/psycopg2/__init__.py", line 122, in connect
    conn = _connect(dsn, connection_factory=connection_factory, **kwasync)
sqlalchemy.exc.OperationalError: (psycopg2.OperationalError) connection to server at "localhost" (::1), port 5432 failed: Connection refused
	Is the server running on that host and accepting TCP/IP connections?
connection to server at "localhost" (127.0.0.1), port 5432 failed: Connection refused
	Is the server running on that host and accepting TCP/IP connections?

(Background on this error at: https://sqlalche.me/e/14/e3q8)

Traceback (most recent call last):
  File "/usr/local/lib/python3.6/dist-packages/sqlalchemy/engine/base.py", line 3250, in _wrap_pool_connect
    return fn()
  File "/usr/local/lib/python3.6/dist-packages/sqlalchemy/pool/base.py", line 310, in connect
    return _ConnectionFairy._checkout(self)
  File "/usr/local/lib/python3.6/dist-packages/sqlalchemy/pool/base.py", line 868, in _checkout
    fairy = _ConnectionRecord.checkout(pool)
  File "/usr/local/lib/python3.6/dist-packages/sqlalchemy/pool/base.py", line 476, in checkout
    rec = pool._do_get()
  File "/usr/local/lib/python3.6/dist-packages/sqlalchemy/pool/impl.py", line 146, in _do_get
    self._dec_overflow()
  File "/usr/local/lib/python3.6/dist-packages/sqlalchemy/util/langhelpers.py", line 72, in __exit__
    with_traceback=exc_tb,
  File "/usr/local/lib/python3.6/dist-packages/sqlalchemy/util/compat.py", line 207, in raise_
    raise exception
  File "/usr/local/lib/python3.6/dist-packages/sqlalchemy/pool/impl.py", line 143, in _do_get
    return self._create_connection()
  File "/usr/local/lib/python3.6/dist-packages/sqlalchemy/pool/base.py", line 256, in _create_connection
    return _ConnectionRecord(self)
  File "/usr/local/lib/python3.6/dist-packages/sqlalchemy/pool/base.py", line 371, in __init__
    self.__connect()
  File "/usr/local/lib/python3.6/dist-packages/sqlalchemy/pool/base.py", line 666, in __connect
    pool.logger.debug("Error on connect(): %s", e)
  File "/usr/local/lib/python3.6/dist-packages/sqlalchemy/util/langhelpers.py", line 72, in __exit__
    with_traceback=exc_tb,
  File "/usr/local/lib/python3.6/dist-packages/sqlalchemy/util/compat.py", line 207, in raise_
    raise exception
  File "/usr/local/lib/python3.6/dist-packages/sqlalchemy/pool/base.py", line 661, in __connect
    self.dbapi_connection = connection = pool._invoke_creator(self)
  File "/usr/local/lib/python3.6/dist-packages/sqlalchemy/engine/create.py", line 590, in connect
    return dialect.connect(*cargs, **cparams)
  File "/usr/local/lib/python3.6/dist-packages/sqlalchemy/engine/default.py", line 597, in connect
    return self.dbapi.connect(*cargs, **cparams)
  File "/usr/local/lib/python3.6/dist-packages/psycopg2/__init__.py", line 122, in connect
    conn = _connect(dsn, connection_factory=connection_factory, **kwasync)
psycopg2.OperationalError: connection to server at "localhost" (::1), port 5432 failed: Connection refused
	Is the server running on that host and accepting TCP/IP connections?
connection to server at "localhost" (127.0.0.1), port 5432 failed: Connection refused
	Is the server running on that host and accepting TCP/IP connections?


The above exception was the direct cause of the following exception:

Traceback (most recent call last):
  File "/tmp/tmp.d9lusb0FGf/orchestra/orchestra/parsers/PilotParser.py", line 73, in run
    pilot.init()
  File "/tmp/tmp.d9lusb0FGf/orchestra/orchestra/Pilot.py", line 54, in init
    self.__devices.init()
  File "/tmp/tmp.d9lusb0FGf/orchestra/orchestra/core/Devices.py", line 34, in init
    for device in self.__db.session().query(Device).filter(Device.nodename==self.nodename).all():
  File "/usr/local/lib/python3.6/dist-packages/sqlalchemy/orm/query.py", line 2759, in all
    return self._iter().all()
  File "/usr/local/lib/python3.6/dist-packages/sqlalchemy/orm/query.py", line 2897, in _iter
    execution_options={"_sa_orm_load_options": self.load_options},
  File "/usr/local/lib/python3.6/dist-packages/sqlalchemy/orm/session.py", line 1691, in execute
    conn = self._connection_for_bind(bind)
  File "/usr/local/lib/python3.6/dist-packages/sqlalchemy/orm/session.py", line 1533, in _connection_for_bind
    engine, execution_options
  File "/usr/local/lib/python3.6/dist-packages/sqlalchemy/orm/session.py", line 747, in _connection_for_bind
    conn = bind.connect()
  File "/usr/local/lib/python3.6/dist-packages/sqlalchemy/engine/base.py", line 3204, in connect
    return self._connection_cls(self, close_with_result=close_with_result)
  File "/usr/local/lib/python3.6/dist-packages/sqlalchemy/engine/base.py", line 96, in __init__
    else engine.raw_connection()
  File "/usr/local/lib/python3.6/dist-packages/sqlalchemy/engine/base.py", line 3283, in raw_connection
    return self._wrap_pool_connect(self.pool.connect, _connection)
  File "/usr/local/lib/python3.6/dist-packages/sqlalchemy/engine/base.py", line 3254, in _wrap_pool_connect
    e, dialect, self
  File "/usr/local/lib/python3.6/dist-packages/sqlalchemy/engine/base.py", line 2101, in _handle_dbapi_exception_noconnection
    sqlalchemy_exception, with_traceback=exc_info[2], from_=e
  File "/usr/local/lib/python3.6/dist-packages/sqlalchemy/util/compat.py", line 207, in raise_
    raise exception
  File "/usr/local/lib/python3.6/dist-packages/sqlalchemy/engine/base.py", line 3250, in _wrap_pool_connect
    return fn()
  File "/usr/local/lib/python3.6/dist-packages/sqlalchemy/pool/base.py", line 310, in connect
    return _ConnectionFairy._checkout(self)
  File "/usr/local/lib/python3.6/dist-packages/sqlalchemy/pool/base.py", line 868, in _checkout
    fairy = _ConnectionRecord.checkout(pool)
  File "/usr/local/lib/python3.6/dist-packages/sqlalchemy/pool/base.py", line 476, in checkout
    rec = pool._do_get()
  File "/usr/local/lib/python3.6/dist-packages/sqlalchemy/pool/impl.py", line 146, in _do_get
    self._dec_overflow()
  File "/usr/local/lib/python3.6/dist-packages/sqlalchemy/util/langhelpers.py", line 72, in __exit__
    with_traceback=exc_tb,
  File "/usr/local/lib/python3.6/dist-packages/sqlalchemy/util/compat.py", line 207, in raise_
    raise exception
  File "/usr/local/lib/python3.6/dist-packages/sqlalchemy/pool/impl.py", line 143, in _do_get
    return self._create_connection()
  File "/usr/local/lib/python3.6/dist-packages/sqlalchemy/pool/base.py", line 256, in _create_connection
    return _ConnectionRecord(self)
  File "/usr/local/lib/python3.6/dist-packages/sqlalchemy/pool/base.py", line 371, in __init__
    self.__connect()
  File "/usr/local/lib/python3.6/dist-packages/sqlalchemy/pool/base.py", line 666, in __connect
    pool.logger.debug("Error on connect(): %s", e)
  File "/usr/local/lib/python3.6/dist-packages/sqlalchemy/util/langhelpers.py", line 72, in __exit__
    with_traceback=exc_tb,
  File "/usr/local/lib/python3.6/dist-packages/sqlalchemy/util/compat.py", line 207, in raise_
    raise exception
  File "/usr/local/lib/python3.6/dist-packages/sqlalchemy/pool/base.py", line 661, in __connect
    self.dbapi_connection = connection = pool._invoke_creator(self)
  File "/usr/local/lib/python3.6/dist-packages/sqlalchemy/engine/create.py", line 590, in connect
    return dialect.connect(*cargs, **cparams)
  File "/usr/local/lib/python3.6/dist-packages/sqlalchemy/engine/default.py", line 597, in connect
    return self.dbapi.connect(*cargs, **cparams)
  File "/usr/local/lib/python3.6/dist-packages/psycopg2/__init__.py", line 122, in connect
    conn = _connect(dsn, connection_factory=connection_factory, **kwasync)
sqlalchemy.exc.OperationalError: (psycopg2.OperationalError) connection to server at "localhost" (::1), port 5432 failed: Connection refused
	Is the server running on that host and accepting TCP/IP connections?
connection to server at "localhost" (127.0.0.1), port 5432 failed: Connection refused
	Is the server running on that host and accepting TCP/IP connections?

(Background on this error at: https://sqlalche.me/e/14/e3q8)
Traceback (most recent call last):
  File "/usr/local/lib/python3.6/dist-packages/sqlalchemy/engine/base.py", line 3250, in _wrap_pool_connect
    return fn()
  File "/usr/local/lib/python3.6/dist-packages/sqlalchemy/pool/base.py", line 310, in connect
    return _ConnectionFairy._checkout(self)
  File "/usr/local/lib/python3.6/dist-packages/sqlalchemy/pool/base.py", line 868, in _checkout
    fairy = _ConnectionRecord.checkout(pool)
  File "/usr/local/lib/python3.6/dist-packages/sqlalchemy/pool/base.py", line 476, in checkout
    rec = pool._do_get()
  File "/usr/local/lib/python3.6/dist-packages/sqlalchemy/pool/impl.py", line 146, in _do_get
    self._dec_overflow()
  File "/usr/local/lib/python3.6/dist-packages/sqlalchemy/util/langhelpers.py", line 72, in __exit__
    with_traceback=exc_tb,
  File "/usr/local/lib/python3.6/dist-packages/sqlalchemy/util/compat.py", line 207, in raise_
    raise exception
  File "/usr/local/lib/python3.6/dist-packages/sqlalchemy/pool/impl.py", line 143, in _do_get
    return self._create_connection()
  File "/usr/local/lib/python3.6/dist-packages/sqlalchemy/pool/base.py", line 256, in _create_connection
    return _ConnectionRecord(self)
  File "/usr/local/lib/python3.6/dist-packages/sqlalchemy/pool/base.py", line 371, in __init__
    self.__connect()
  File "/usr/local/lib/python3.6/dist-packages/sqlalchemy/pool/base.py", line 666, in __connect
    pool.logger.debug("Error on connect(): %s", e)
  File "/usr/local/lib/python3.6/dist-packages/sqlalchemy/util/langhelpers.py", line 72, in __exit__
    with_traceback=exc_tb,
  File "/usr/local/lib/python3.6/dist-packages/sqlalchemy/util/compat.py", line 207, in raise_
    raise exception
  File "/usr/local/lib/python3.6/dist-packages/sqlalchemy/pool/base.py", line 661, in __connect
    self.dbapi_connection = connection = pool._invoke_creator(self)
  File "/usr/local/lib/python3.6/dist-packages/sqlalchemy/engine/create.py", line 590, in connect
    return dialect.connect(*cargs, **cparams)
  File "/usr/local/lib/python3.6/dist-packages/sqlalchemy/engine/default.py", line 597, in connect
    return self.dbapi.connect(*cargs, **cparams)
  File "/usr/local/lib/python3.6/dist-packages/psycopg2/__init__.py", line 122, in connect
    conn = _connect(dsn, connection_factory=connection_factory, **kwasync)
psycopg2.OperationalError: connection to server at "localhost" (::1), port 5432 failed: Connection refused
	Is the server running on that host and accepting TCP/IP connections?
connection to server at "localhost" (127.0.0.1), port 5432 failed: Connection refused
	Is the server running on that host and accepting TCP/IP connections?


The above exception was the direct cause of the following exception:

Traceback (most recent call last):
  File "/tmp/tmp.d9lusb0FGf/orchestra/orchestra/parsers/PilotParser.py", line 73, in run
    pilot.init()
  File "/tmp/tmp.d9lusb0FGf/orchestra/orchestra/Pilot.py", line 54, in init
    self.__devices.init()
  File "/tmp/tmp.d9lusb0FGf/orchestra/orchestra/core/Devices.py", line 34, in init
    for device in self.__db.session().query(Device).filter(Device.nodename==self.nodename).all():
  File "/usr/local/lib/python3.6/dist-packages/sqlalchemy/orm/query.py", line 2759, in all
    return self._iter().all()
  File "/usr/local/lib/python3.6/dist-packages/sqlalchemy/orm/query.py", line 2897, in _iter
    execution_options={"_sa_orm_load_options": self.load_options},
  File "/usr/local/lib/python3.6/dist-packages/sqlalchemy/orm/session.py", line 1691, in execute
    conn = self._connection_for_bind(bind)
  File "/usr/local/lib/python3.6/dist-packages/sqlalchemy/orm/session.py", line 1533, in _connection_for_bind
    engine, execution_options
  File "/usr/local/lib/python3.6/dist-packages/sqlalchemy/orm/session.py", line 747, in _connection_for_bind
    conn = bind.connect()
  File "/usr/local/lib/python3.6/dist-packages/sqlalchemy/engine/base.py", line 3204, in connect
    return self._connection_cls(self, close_with_result=close_with_result)
  File "/usr/local/lib/python3.6/dist-packages/sqlalchemy/engine/base.py", line 96, in __init__
    else engine.raw_connection()
  File "/usr/local/lib/python3.6/dist-packages/sqlalchemy/engine/base.py", line 3283, in raw_connection
    return self._wrap_pool_connect(self.pool.connect, _connection)
  File "/usr/local/lib/python3.6/dist-packages/sqlalchemy/engine/base.py", line 3254, in _wrap_pool_connect
    e, dialect, self
  File "/usr/local/lib/python3.6/dist-packages/sqlalchemy/engine/base.py", line 2101, in _handle_dbapi_exception_noconnection
    sqlalchemy_exception, with_traceback=exc_info[2], from_=e
  File "/usr/local/lib/python3.6/dist-packages/sqlalchemy/util/compat.py", line 207, in raise_
    raise exception
  File "/usr/local/lib/python3.6/dist-packages/sqlalchemy/engine/base.py", line 3250, in _wrap_pool_connect
    return fn()
  File "/usr/local/lib/python3.6/dist-packages/sqlalchemy/pool/base.py", line 310, in connect
    return _ConnectionFairy._checkout(self)
  File "/usr/local/lib/python3.6/dist-packages/sqlalchemy/pool/base.py", line 868, in _checkout
    fairy = _ConnectionRecord.checkout(pool)
  File "/usr/local/lib/python3.6/dist-packages/sqlalchemy/pool/base.py", line 476, in checkout
    rec = pool._do_get()
  File "/usr/local/lib/python3.6/dist-packages/sqlalchemy/pool/impl.py", line 146, in _do_get
    self._dec_overflow()
  File "/usr/local/lib/python3.6/dist-packages/sqlalchemy/util/langhelpers.py", line 72, in __exit__
    with_traceback=exc_tb,
  File "/usr/local/lib/python3.6/dist-packages/sqlalchemy/util/compat.py", line 207, in raise_
    raise exception
  File "/usr/local/lib/python3.6/dist-packages/sqlalchemy/pool/impl.py", line 143, in _do_get
    return self._create_connection()
  File "/usr/local/lib/python3.6/dist-packages/sqlalchemy/pool/base.py", line 256, in _create_connection
    return _ConnectionRecord(self)
  File "/usr/local/lib/python3.6/dist-packages/sqlalchemy/pool/base.py", line 371, in __init__
    self.__connect()
  File "/usr/local/lib/python3.6/dist-packages/sqlalchemy/pool/base.py", line 666, in __connect
    pool.logger.debug("Error on connect(): %s", e)
  File "/usr/local/lib/python3.6/dist-packages/sqlalchemy/util/langhelpers.py", line 72, in __exit__
    with_traceback=exc_tb,
  File "/usr/local/lib/python3.6/dist-packages/sqlalchemy/util/compat.py", line 207, in raise_
    raise exception
  File "/usr/local/lib/python3.6/dist-packages/sqlalchemy/pool/base.py", line 661, in __connect
    self.dbapi_connection = connection = pool._invoke_creator(self)
  File "/usr/local/lib/python3.6/dist-packages/sqlalchemy/engine/create.py", line 590, in connect
    return dialect.connect(*cargs, **cparams)
  File "/usr/local/lib/python3.6/dist-packages/sqlalchemy/engine/default.py", line 597, in connect
    return self.dbapi.connect(*cargs, **cparams)
  File "/usr/local/lib/python3.6/dist-packages/psycopg2/__init__.py", line 122, in connect
    conn = _connect(dsn, connection_factory=connection_factory, **kwasync)
sqlalchemy.exc.OperationalError: (psycopg2.OperationalError) connection to server at "localhost" (::1), port 5432 failed: Connection refused
	Is the server running on that host and accepting TCP/IP connections?
connection to server at "localhost" (127.0.0.1), port 5432 failed: Connection refused
	Is the server running on that host and accepting TCP/IP connections?

(Background on this error at: https://sqlalche.me/e/14/e3q8)

During handling of the above exception, another exception occurred:

Traceback (most recent call last):
  File "/tmp/tmp.d9lusb0FGf/orchestra/orchestra/mailing/Postman.py", line 45, in __send
    server.login(self.__myEmail, self.__myPassword)
  File "/usr/lib/python3.6/smtplib.py", line 721, in login
    initial_response_ok=initial_response_ok)
  File "/usr/lib/python3.6/smtplib.py", line 631, in auth
    (code, resp) = self.docmd("AUTH", mechanism + " " + response)
  File "/usr/lib/python3.6/smtplib.py", line 421, in docmd
    return self.getreply()
  File "/usr/lib/python3.6/smtplib.py", line 394, in getreply
    raise SMTPServerDisconnected("Connection unexpectedly closed")
smtplib.SMTPServerDisconnected: Connection unexpectedly closed
Traceback (most recent call last):
  File "/usr/local/lib/python3.6/dist-packages/sqlalchemy/engine/base.py", line 3250, in _wrap_pool_connect
    return fn()
  File "/usr/local/lib/python3.6/dist-packages/sqlalchemy/pool/base.py", line 310, in connect
    return _ConnectionFairy._checkout(self)
  File "/usr/local/lib/python3.6/dist-packages/sqlalchemy/pool/base.py", line 868, in _checkout
    fairy = _ConnectionRecord.checkout(pool)
  File "/usr/local/lib/python3.6/dist-packages/sqlalchemy/pool/base.py", line 476, in checkout
    rec = pool._do_get()
  File "/usr/local/lib/python3.6/dist-packages/sqlalchemy/pool/impl.py", line 146, in _do_get
    self._dec_overflow()
  File "/usr/local/lib/python3.6/dist-packages/sqlalchemy/util/langhelpers.py", line 72, in __exit__
    with_traceback=exc_tb,
  File "/usr/local/lib/python3.6/dist-packages/sqlalchemy/util/compat.py", line 207, in raise_
    raise exception
  File "/usr/local/lib/python3.6/dist-packages/sqlalchemy/pool/impl.py", line 143, in _do_get
    return self._create_connection()
  File "/usr/local/lib/python3.6/dist-packages/sqlalchemy/pool/base.py", line 256, in _create_connection
    return _ConnectionRecord(self)
  File "/usr/local/lib/python3.6/dist-packages/sqlalchemy/pool/base.py", line 371, in __init__
    self.__connect()
  File "/usr/local/lib/python3.6/dist-packages/sqlalchemy/pool/base.py", line 666, in __connect
    pool.logger.debug("Error on connect(): %s", e)
  File "/usr/local/lib/python3.6/dist-packages/sqlalchemy/util/langhelpers.py", line 72, in __exit__
    with_traceback=exc_tb,
  File "/usr/local/lib/python3.6/dist-packages/sqlalchemy/util/compat.py", line 207, in raise_
    raise exception
  File "/usr/local/lib/python3.6/dist-packages/sqlalchemy/pool/base.py", line 661, in __connect
    self.dbapi_connection = connection = pool._invoke_creator(self)
  File "/usr/local/lib/python3.6/dist-packages/sqlalchemy/engine/create.py", line 590, in connect
    return dialect.connect(*cargs, **cparams)
  File "/usr/local/lib/python3.6/dist-packages/sqlalchemy/engine/default.py", line 597, in connect
    return self.dbapi.connect(*cargs, **cparams)
  File "/usr/local/lib/python3.6/dist-packages/psycopg2/__init__.py", line 122, in connect
    conn = _connect(dsn, connection_factory=connection_factory, **kwasync)
psycopg2.OperationalError: connection to server at "localhost" (::1), port 5432 failed: Connection refused
	Is the server running on that host and accepting TCP/IP connections?
connection to server at "localhost" (127.0.0.1), port 5432 failed: Connection refused
	Is the server running on that host and accepting TCP/IP connections?


The above exception was the direct cause of the following exception:

Traceback (most recent call last):
  File "/tmp/tmp.d9lusb0FGf/orchestra/orchestra/parsers/PilotParser.py", line 73, in run
    pilot.init()
  File "/tmp/tmp.d9lusb0FGf/orchestra/orchestra/Pilot.py", line 54, in init
    self.__devices.init()
  File "/tmp/tmp.d9lusb0FGf/orchestra/orchestra/core/Devices.py", line 34, in init
    for device in self.__db.session().query(Device).filter(Device.nodename==self.nodename).all():
  File "/usr/local/lib/python3.6/dist-packages/sqlalchemy/orm/query.py", line 2759, in all
    return self._iter().all()
  File "/usr/local/lib/python3.6/dist-packages/sqlalchemy/orm/query.py", line 2897, in _iter
    execution_options={"_sa_orm_load_options": self.load_options},
  File "/usr/local/lib/python3.6/dist-packages/sqlalchemy/orm/session.py", line 1691, in execute
    conn = self._connection_for_bind(bind)
  File "/usr/local/lib/python3.6/dist-packages/sqlalchemy/orm/session.py", line 1533, in _connection_for_bind
    engine, execution_options
  File "/usr/local/lib/python3.6/dist-packages/sqlalchemy/orm/session.py", line 747, in _connection_for_bind
    conn = bind.connect()
  File "/usr/local/lib/python3.6/dist-packages/sqlalchemy/engine/base.py", line 3204, in connect
    return self._connection_cls(self, close_with_result=close_with_result)
  File "/usr/local/lib/python3.6/dist-packages/sqlalchemy/engine/base.py", line 96, in __init__
    else engine.raw_connection()
  File "/usr/local/lib/python3.6/dist-packages/sqlalchemy/engine/base.py", line 3283, in raw_connection
    return self._wrap_pool_connect(self.pool.connect, _connection)
  File "/usr/local/lib/python3.6/dist-packages/sqlalchemy/engine/base.py", line 3254, in _wrap_pool_connect
    e, dialect, self
  File "/usr/local/lib/python3.6/dist-packages/sqlalchemy/engine/base.py", line 2101, in _handle_dbapi_exception_noconnection
    sqlalchemy_exception, with_traceback=exc_info[2], from_=e
  File "/usr/local/lib/python3.6/dist-packages/sqlalchemy/util/compat.py", line 207, in raise_
    raise exception
  File "/usr/local/lib/python3.6/dist-packages/sqlalchemy/engine/base.py", line 3250, in _wrap_pool_connect
    return fn()
  File "/usr/local/lib/python3.6/dist-packages/sqlalchemy/pool/base.py", line 310, in connect
    return _ConnectionFairy._checkout(self)
  File "/usr/local/lib/python3.6/dist-packages/sqlalchemy/pool/base.py", line 868, in _checkout
    fairy = _ConnectionRecord.checkout(pool)
  File "/usr/local/lib/python3.6/dist-packages/sqlalchemy/pool/base.py", line 476, in checkout
    rec = pool._do_get()
  File "/usr/local/lib/python3.6/dist-packages/sqlalchemy/pool/impl.py", line 146, in _do_get
    self._dec_overflow()
  File "/usr/local/lib/python3.6/dist-packages/sqlalchemy/util/langhelpers.py", line 72, in __exit__
    with_traceback=exc_tb,
  File "/usr/local/lib/python3.6/dist-packages/sqlalchemy/util/compat.py", line 207, in raise_
    raise exception
  File "/usr/local/lib/python3.6/dist-packages/sqlalchemy/pool/impl.py", line 143, in _do_get
    return self._create_connection()
  File "/usr/local/lib/python3.6/dist-packages/sqlalchemy/pool/base.py", line 256, in _create_connection
    return _ConnectionRecord(self)
  File "/usr/local/lib/python3.6/dist-packages/sqlalchemy/pool/base.py", line 371, in __init__
    self.__connect()
  File "/usr/local/lib/python3.6/dist-packages/sqlalchemy/pool/base.py", line 666, in __connect
    pool.logger.debug("Error on connect(): %s", e)
  File "/usr/local/lib/python3.6/dist-packages/sqlalchemy/util/langhelpers.py", line 72, in __exit__
    with_traceback=exc_tb,
  File "/usr/local/lib/python3.6/dist-packages/sqlalchemy/util/compat.py", line 207, in raise_
    raise exception
  File "/usr/local/lib/python3.6/dist-packages/sqlalchemy/pool/base.py", line 661, in __connect
    self.dbapi_connection = connection = pool._invoke_creator(self)
  File "/usr/local/lib/python3.6/dist-packages/sqlalchemy/engine/create.py", line 590, in connect
    return dialect.connect(*cargs, **cparams)
  File "/usr/local/lib/python3.6/dist-packages/sqlalchemy/engine/default.py", line 597, in connect
    return self.dbapi.connect(*cargs, **cparams)
  File "/usr/local/lib/python3.6/dist-packages/psycopg2/__init__.py", line 122, in connect
    conn = _connect(dsn, connection_factory=connection_factory, **kwasync)
sqlalchemy.exc.OperationalError: (psycopg2.OperationalError) connection to server at "localhost" (::1), port 5432 failed: Connection refused
	Is the server running on that host and accepting TCP/IP connections?
connection to server at "localhost" (127.0.0.1), port 5432 failed: Connection refused
	Is the server running on that host and accepting TCP/IP connections?

(Background on this error at: https://sqlalche.me/e/14/e3q8)

Traceback (most recent call last):
  File "/usr/local/lib/python3.6/dist-packages/sqlalchemy/engine/base.py", line 3250, in _wrap_pool_connect
    return fn()
  File "/usr/local/lib/python3.6/dist-packages/sqlalchemy/pool/base.py", line 310, in connect
    return _ConnectionFairy._checkout(self)
  File "/usr/local/lib/python3.6/dist-packages/sqlalchemy/pool/base.py", line 868, in _checkout
    fairy = _ConnectionRecord.checkout(pool)
  File "/usr/local/lib/python3.6/dist-packages/sqlalchemy/pool/base.py", line 476, in checkout
    rec = pool._do_get()
  File "/usr/local/lib/python3.6/dist-packages/sqlalchemy/pool/impl.py", line 146, in _do_get
    self._dec_overflow()
  File "/usr/local/lib/python3.6/dist-packages/sqlalchemy/util/langhelpers.py", line 72, in __exit__
    with_traceback=exc_tb,
  File "/usr/local/lib/python3.6/dist-packages/sqlalchemy/util/compat.py", line 207, in raise_
    raise exception
  File "/usr/local/lib/python3.6/dist-packages/sqlalchemy/pool/impl.py", line 143, in _do_get
    return self._create_connection()
  File "/usr/local/lib/python3.6/dist-packages/sqlalchemy/pool/base.py", line 256, in _create_connection
    return _ConnectionRecord(self)
  File "/usr/local/lib/python3.6/dist-packages/sqlalchemy/pool/base.py", line 371, in __init__
    self.__connect()
  File "/usr/local/lib/python3.6/dist-packages/sqlalchemy/pool/base.py", line 666, in __connect
    pool.logger.debug("Error on connect(): %s", e)
  File "/usr/local/lib/python3.6/dist-packages/sqlalchemy/util/langhelpers.py", line 72, in __exit__
    with_traceback=exc_tb,
  File "/usr/local/lib/python3.6/dist-packages/sqlalchemy/util/compat.py", line 207, in raise_
    raise exception
  File "/usr/local/lib/python3.6/dist-packages/sqlalchemy/pool/base.py", line 661, in __connect
    self.dbapi_connection = connection = pool._invoke_creator(self)
  File "/usr/local/lib/python3.6/dist-packages/sqlalchemy/engine/create.py", line 590, in connect
    return dialect.connect(*cargs, **cparams)
  File "/usr/local/lib/python3.6/dist-packages/sqlalchemy/engine/default.py", line 597, in connect
    return self.dbapi.connect(*cargs, **cparams)
  File "/usr/local/lib/python3.6/dist-packages/psycopg2/__init__.py", line 122, in connect
    conn = _connect(dsn, connection_factory=connection_factory, **kwasync)
psycopg2.OperationalError: connection to server at "localhost" (::1), port 5432 failed: Connection refused
	Is the server running on that host and accepting TCP/IP connections?
connection to server at "localhost" (127.0.0.1), port 5432 failed: Connection refused
	Is the server running on that host and accepting TCP/IP connections?


The above exception was the direct cause of the following exception:

Traceback (most recent call last):
  File "/tmp/tmp.d9lusb0FGf/orchestra/orchestra/parsers/PilotParser.py", line 73, in run
    pilot.init()
  File "/tmp/tmp.d9lusb0FGf/orchestra/orchestra/Pilot.py", line 54, in init
    self.__devices.init()
  File "/tmp/tmp.d9lusb0FGf/orchestra/orchestra/core/Devices.py", line 34, in init
    for device in self.__db.session().query(Device).filter(Device.nodename==self.nodename).all():
  File "/usr/local/lib/python3.6/dist-packages/sqlalchemy/orm/query.py", line 2759, in all
    return self._iter().all()
  File "/usr/local/lib/python3.6/dist-packages/sqlalchemy/orm/query.py", line 2897, in _iter
    execution_options={"_sa_orm_load_options": self.load_options},
  File "/usr/local/lib/python3.6/dist-packages/sqlalchemy/orm/session.py", line 1691, in execute
    conn = self._connection_for_bind(bind)
  File "/usr/local/lib/python3.6/dist-packages/sqlalchemy/orm/session.py", line 1533, in _connection_for_bind
    engine, execution_options
  File "/usr/local/lib/python3.6/dist-packages/sqlalchemy/orm/session.py", line 747, in _connection_for_bind
    conn = bind.connect()
  File "/usr/local/lib/python3.6/dist-packages/sqlalchemy/engine/base.py", line 3204, in connect
    return self._connection_cls(self, close_with_result=close_with_result)
  File "/usr/local/lib/python3.6/dist-packages/sqlalchemy/engine/base.py", line 96, in __init__
    else engine.raw_connection()
  File "/usr/local/lib/python3.6/dist-packages/sqlalchemy/engine/base.py", line 3283, in raw_connection
    return self._wrap_pool_connect(self.pool.connect, _connection)
  File "/usr/local/lib/python3.6/dist-packages/sqlalchemy/engine/base.py", line 3254, in _wrap_pool_connect
    e, dialect, self
  File "/usr/local/lib/python3.6/dist-packages/sqlalchemy/engine/base.py", line 2101, in _handle_dbapi_exception_noconnection
    sqlalchemy_exception, with_traceback=exc_info[2], from_=e
  File "/usr/local/lib/python3.6/dist-packages/sqlalchemy/util/compat.py", line 207, in raise_
    raise exception
  File "/usr/local/lib/python3.6/dist-packages/sqlalchemy/engine/base.py", line 3250, in _wrap_pool_connect
    return fn()
  File "/usr/local/lib/python3.6/dist-packages/sqlalchemy/pool/base.py", line 310, in connect
    return _ConnectionFairy._checkout(self)
  File "/usr/local/lib/python3.6/dist-packages/sqlalchemy/pool/base.py", line 868, in _checkout
    fairy = _ConnectionRecord.checkout(pool)
  File "/usr/local/lib/python3.6/dist-packages/sqlalchemy/pool/base.py", line 476, in checkout
    rec = pool._do_get()
  File "/usr/local/lib/python3.6/dist-packages/sqlalchemy/pool/impl.py", line 146, in _do_get
    self._dec_overflow()
  File "/usr/local/lib/python3.6/dist-packages/sqlalchemy/util/langhelpers.py", line 72, in __exit__
    with_traceback=exc_tb,
  File "/usr/local/lib/python3.6/dist-packages/sqlalchemy/util/compat.py", line 207, in raise_
    raise exception
  File "/usr/local/lib/python3.6/dist-packages/sqlalchemy/pool/impl.py", line 143, in _do_get
    return self._create_connection()
  File "/usr/local/lib/python3.6/dist-packages/sqlalchemy/pool/base.py", line 256, in _create_connection
    return _ConnectionRecord(self)
  File "/usr/local/lib/python3.6/dist-packages/sqlalchemy/pool/base.py", line 371, in __init__
    self.__connect()
  File "/usr/local/lib/python3.6/dist-packages/sqlalchemy/pool/base.py", line 666, in __connect
    pool.logger.debug("Error on connect(): %s", e)
  File "/usr/local/lib/python3.6/dist-packages/sqlalchemy/util/langhelpers.py", line 72, in __exit__
    with_traceback=exc_tb,
  File "/usr/local/lib/python3.6/dist-packages/sqlalchemy/util/compat.py", line 207, in raise_
    raise exception
  File "/usr/local/lib/python3.6/dist-packages/sqlalchemy/pool/base.py", line 661, in __connect
    self.dbapi_connection = connection = pool._invoke_creator(self)
  File "/usr/local/lib/python3.6/dist-packages/sqlalchemy/engine/create.py", line 590, in connect
    return dialect.connect(*cargs, **cparams)
  File "/usr/local/lib/python3.6/dist-packages/sqlalchemy/engine/default.py", line 597, in connect
    return self.dbapi.connect(*cargs, **cparams)
  File "/usr/local/lib/python3.6/dist-packages/psycopg2/__init__.py", line 122, in connect
    conn = _connect(dsn, connection_factory=connection_factory, **kwasync)
sqlalchemy.exc.OperationalError: (psycopg2.OperationalError) connection to server at "localhost" (::1), port 5432 failed: Connection refused
	Is the server running on that host and accepting TCP/IP connections?
connection to server at "localhost" (127.0.0.1), port 5432 failed: Connection refused
	Is the server running on that host and accepting TCP/IP connections?

(Background on this error at: https://sqlalche.me/e/14/e3q8)
Traceback (most recent call last):
  File "/usr/local/lib/python3.6/dist-packages/sqlalchemy/engine/base.py", line 3250, in _wrap_pool_connect
    return fn()
  File "/usr/local/lib/python3.6/dist-packages/sqlalchemy/pool/base.py", line 310, in connect
    return _ConnectionFairy._checkout(self)
  File "/usr/local/lib/python3.6/dist-packages/sqlalchemy/pool/base.py", line 868, in _checkout
    fairy = _ConnectionRecord.checkout(pool)
  File "/usr/local/lib/python3.6/dist-packages/sqlalchemy/pool/base.py", line 476, in checkout
    rec = pool._do_get()
  File "/usr/local/lib/python3.6/dist-packages/sqlalchemy/pool/impl.py", line 146, in _do_get
    self._dec_overflow()
  File "/usr/local/lib/python3.6/dist-packages/sqlalchemy/util/langhelpers.py", line 72, in __exit__
    with_traceback=exc_tb,
  File "/usr/local/lib/python3.6/dist-packages/sqlalchemy/util/compat.py", line 207, in raise_
    raise exception
  File "/usr/local/lib/python3.6/dist-packages/sqlalchemy/pool/impl.py", line 143, in _do_get
    return self._create_connection()
  File "/usr/local/lib/python3.6/dist-packages/sqlalchemy/pool/base.py", line 256, in _create_connection
    return _ConnectionRecord(self)
  File "/usr/local/lib/python3.6/dist-packages/sqlalchemy/pool/base.py", line 371, in __init__
    self.__connect()
  File "/usr/local/lib/python3.6/dist-packages/sqlalchemy/pool/base.py", line 666, in __connect
    pool.logger.debug("Error on connect(): %s", e)
  File "/usr/local/lib/python3.6/dist-packages/sqlalchemy/util/langhelpers.py", line 72, in __exit__
    with_traceback=exc_tb,
  File "/usr/local/lib/python3.6/dist-packages/sqlalchemy/util/compat.py", line 207, in raise_
    raise exception
  File "/usr/local/lib/python3.6/dist-packages/sqlalchemy/pool/base.py", line 661, in __connect
    self.dbapi_connection = connection = pool._invoke_creator(self)
  File "/usr/local/lib/python3.6/dist-packages/sqlalchemy/engine/create.py", line 590, in connect
    return dialect.connect(*cargs, **cparams)
  File "/usr/local/lib/python3.6/dist-packages/sqlalchemy/engine/default.py", line 597, in connect
    return self.dbapi.connect(*cargs, **cparams)
  File "/usr/local/lib/python3.6/dist-packages/psycopg2/__init__.py", line 122, in connect
    conn = _connect(dsn, connection_factory=connection_factory, **kwasync)
psycopg2.OperationalError: connection to server at "localhost" (::1), port 5432 failed: Connection refused
	Is the server running on that host and accepting TCP/IP connections?
connection to server at "localhost" (127.0.0.1), port 5432 failed: Connection refused
	Is the server running on that host and accepting TCP/IP connections?


The above exception was the direct cause of the following exception:

Traceback (most recent call last):
  File "/tmp/tmp.d9lusb0FGf/orchestra/orchestra/parsers/PilotParser.py", line 73, in run
    pilot.init()
  File "/tmp/tmp.d9lusb0FGf/orchestra/orchestra/Pilot.py", line 54, in init
    self.__devices.init()
  File "/tmp/tmp.d9lusb0FGf/orchestra/orchestra/core/Devices.py", line 34, in init
    for device in self.__db.session().query(Device).filter(Device.nodename==self.nodename).all():
  File "/usr/local/lib/python3.6/dist-packages/sqlalchemy/orm/query.py", line 2759, in all
    return self._iter().all()
  File "/usr/local/lib/python3.6/dist-packages/sqlalchemy/orm/query.py", line 2897, in _iter
    execution_options={"_sa_orm_load_options": self.load_options},
  File "/usr/local/lib/python3.6/dist-packages/sqlalchemy/orm/session.py", line 1691, in execute
    conn = self._connection_for_bind(bind)
  File "/usr/local/lib/python3.6/dist-packages/sqlalchemy/orm/session.py", line 1533, in _connection_for_bind
    engine, execution_options
  File "/usr/local/lib/python3.6/dist-packages/sqlalchemy/orm/session.py", line 747, in _connection_for_bind
    conn = bind.connect()
  File "/usr/local/lib/python3.6/dist-packages/sqlalchemy/engine/base.py", line 3204, in connect
    return self._connection_cls(self, close_with_result=close_with_result)
  File "/usr/local/lib/python3.6/dist-packages/sqlalchemy/engine/base.py", line 96, in __init__
    else engine.raw_connection()
  File "/usr/local/lib/python3.6/dist-packages/sqlalchemy/engine/base.py", line 3283, in raw_connection
    return self._wrap_pool_connect(self.pool.connect, _connection)
  File "/usr/local/lib/python3.6/dist-packages/sqlalchemy/engine/base.py", line 3254, in _wrap_pool_connect
    e, dialect, self
  File "/usr/local/lib/python3.6/dist-packages/sqlalchemy/engine/base.py", line 2101, in _handle_dbapi_exception_noconnection
    sqlalchemy_exception, with_traceback=exc_info[2], from_=e
  File "/usr/local/lib/python3.6/dist-packages/sqlalchemy/util/compat.py", line 207, in raise_
    raise exception
  File "/usr/local/lib/python3.6/dist-packages/sqlalchemy/engine/base.py", line 3250, in _wrap_pool_connect
    return fn()
  File "/usr/local/lib/python3.6/dist-packages/sqlalchemy/pool/base.py", line 310, in connect
    return _ConnectionFairy._checkout(self)
  File "/usr/local/lib/python3.6/dist-packages/sqlalchemy/pool/base.py", line 868, in _checkout
    fairy = _ConnectionRecord.checkout(pool)
  File "/usr/local/lib/python3.6/dist-packages/sqlalchemy/pool/base.py", line 476, in checkout
    rec = pool._do_get()
  File "/usr/local/lib/python3.6/dist-packages/sqlalchemy/pool/impl.py", line 146, in _do_get
    self._dec_overflow()
  File "/usr/local/lib/python3.6/dist-packages/sqlalchemy/util/langhelpers.py", line 72, in __exit__
    with_traceback=exc_tb,
  File "/usr/local/lib/python3.6/dist-packages/sqlalchemy/util/compat.py", line 207, in raise_
    raise exception
  File "/usr/local/lib/python3.6/dist-packages/sqlalchemy/pool/impl.py", line 143, in _do_get
    return self._create_connection()
  File "/usr/local/lib/python3.6/dist-packages/sqlalchemy/pool/base.py", line 256, in _create_connection
    return _ConnectionRecord(self)
  File "/usr/local/lib/python3.6/dist-packages/sqlalchemy/pool/base.py", line 371, in __init__
    self.__connect()
  File "/usr/local/lib/python3.6/dist-packages/sqlalchemy/pool/base.py", line 666, in __connect
    pool.logger.debug("Error on connect(): %s", e)
  File "/usr/local/lib/python3.6/dist-packages/sqlalchemy/util/langhelpers.py", line 72, in __exit__
    with_traceback=exc_tb,
  File "/usr/local/lib/python3.6/dist-packages/sqlalchemy/util/compat.py", line 207, in raise_
    raise exception
  File "/usr/local/lib/python3.6/dist-packages/sqlalchemy/pool/base.py", line 661, in __connect
    self.dbapi_connection = connection = pool._invoke_creator(self)
  File "/usr/local/lib/python3.6/dist-packages/sqlalchemy/engine/create.py", line 590, in connect
    return dialect.connect(*cargs, **cparams)
  File "/usr/local/lib/python3.6/dist-packages/sqlalchemy/engine/default.py", line 597, in connect
    return self.dbapi.connect(*cargs, **cparams)
  File "/usr/local/lib/python3.6/dist-packages/psycopg2/__init__.py", line 122, in connect
    conn = _connect(dsn, connection_factory=connection_factory, **kwasync)
sqlalchemy.exc.OperationalError: (psycopg2.OperationalError) connection to server at "localhost" (::1), port 5432 failed: Connection refused
	Is the server running on that host and accepting TCP/IP connections?
connection to server at "localhost" (127.0.0.1), port 5432 failed: Connection refused
	Is the server running on that host and accepting TCP/IP connections?

(Background on this error at: https://sqlalche.me/e/14/e3q8)

During handling of the above exception, another exception occurred:

Traceback (most recent call last):
  File "/tmp/tmp.d9lusb0FGf/orchestra/orchestra/mailing/Postman.py", line 45, in __send
    server.login(self.__myEmail, self.__myPassword)
  File "/usr/lib/python3.6/smtplib.py", line 721, in login
    initial_response_ok=initial_response_ok)
  File "/usr/lib/python3.6/smtplib.py", line 631, in auth
    (code, resp) = self.docmd("AUTH", mechanism + " " + response)
  File "/usr/lib/python3.6/smtplib.py", line 421, in docmd
    return self.getreply()
  File "/usr/lib/python3.6/smtplib.py", line 394, in getreply
    raise SMTPServerDisconnected("Connection unexpectedly closed")
smtplib.SMTPServerDisconnected: Connection unexpectedly closed
Traceback (most recent call last):
  File "/usr/local/lib/python3.6/dist-packages/sqlalchemy/engine/base.py", line 3250, in _wrap_pool_connect
    return fn()
  File "/usr/local/lib/python3.6/dist-packages/sqlalchemy/pool/base.py", line 310, in connect
    return _ConnectionFairy._checkout(self)
  File "/usr/local/lib/python3.6/dist-packages/sqlalchemy/pool/base.py", line 868, in _checkout
    fairy = _ConnectionRecord.checkout(pool)
  File "/usr/local/lib/python3.6/dist-packages/sqlalchemy/pool/base.py", line 476, in checkout
    rec = pool._do_get()
  File "/usr/local/lib/python3.6/dist-packages/sqlalchemy/pool/impl.py", line 146, in _do_get
    self._dec_overflow()
  File "/usr/local/lib/python3.6/dist-packages/sqlalchemy/util/langhelpers.py", line 72, in __exit__
    with_traceback=exc_tb,
  File "/usr/local/lib/python3.6/dist-packages/sqlalchemy/util/compat.py", line 207, in raise_
    raise exception
  File "/usr/local/lib/python3.6/dist-packages/sqlalchemy/pool/impl.py", line 143, in _do_get
    return self._create_connection()
  File "/usr/local/lib/python3.6/dist-packages/sqlalchemy/pool/base.py", line 256, in _create_connection
    return _ConnectionRecord(self)
  File "/usr/local/lib/python3.6/dist-packages/sqlalchemy/pool/base.py", line 371, in __init__
    self.__connect()
  File "/usr/local/lib/python3.6/dist-packages/sqlalchemy/pool/base.py", line 666, in __connect
    pool.logger.debug("Error on connect(): %s", e)
  File "/usr/local/lib/python3.6/dist-packages/sqlalchemy/util/langhelpers.py", line 72, in __exit__
    with_traceback=exc_tb,
  File "/usr/local/lib/python3.6/dist-packages/sqlalchemy/util/compat.py", line 207, in raise_
    raise exception
  File "/usr/local/lib/python3.6/dist-packages/sqlalchemy/pool/base.py", line 661, in __connect
    self.dbapi_connection = connection = pool._invoke_creator(self)
  File "/usr/local/lib/python3.6/dist-packages/sqlalchemy/engine/create.py", line 590, in connect
    return dialect.connect(*cargs, **cparams)
  File "/usr/local/lib/python3.6/dist-packages/sqlalchemy/engine/default.py", line 597, in connect
    return self.dbapi.connect(*cargs, **cparams)
  File "/usr/local/lib/python3.6/dist-packages/psycopg2/__init__.py", line 122, in connect
    conn = _connect(dsn, connection_factory=connection_factory, **kwasync)
psycopg2.OperationalError: connection to server at "localhost" (::1), port 5432 failed: Connection refused
	Is the server running on that host and accepting TCP/IP connections?
connection to server at "localhost" (127.0.0.1), port 5432 failed: Connection refused
	Is the server running on that host and accepting TCP/IP connections?


The above exception was the direct cause of the following exception:

Traceback (most recent call last):
  File "/tmp/tmp.d9lusb0FGf/orchestra/orchestra/parsers/PilotParser.py", line 73, in run
    pilot.init()
  File "/tmp/tmp.d9lusb0FGf/orchestra/orchestra/Pilot.py", line 54, in init
    self.__devices.init()
  File "/tmp/tmp.d9lusb0FGf/orchestra/orchestra/core/Devices.py", line 34, in init
    for device in self.__db.session().query(Device).filter(Device.nodename==self.nodename).all():
  File "/usr/local/lib/python3.6/dist-packages/sqlalchemy/orm/query.py", line 2759, in all
    return self._iter().all()
  File "/usr/local/lib/python3.6/dist-packages/sqlalchemy/orm/query.py", line 2897, in _iter
    execution_options={"_sa_orm_load_options": self.load_options},
  File "/usr/local/lib/python3.6/dist-packages/sqlalchemy/orm/session.py", line 1691, in execute
    conn = self._connection_for_bind(bind)
  File "/usr/local/lib/python3.6/dist-packages/sqlalchemy/orm/session.py", line 1533, in _connection_for_bind
    engine, execution_options
  File "/usr/local/lib/python3.6/dist-packages/sqlalchemy/orm/session.py", line 747, in _connection_for_bind
    conn = bind.connect()
  File "/usr/local/lib/python3.6/dist-packages/sqlalchemy/engine/base.py", line 3204, in connect
    return self._connection_cls(self, close_with_result=close_with_result)
  File "/usr/local/lib/python3.6/dist-packages/sqlalchemy/engine/base.py", line 96, in __init__
    else engine.raw_connection()
  File "/usr/local/lib/python3.6/dist-packages/sqlalchemy/engine/base.py", line 3283, in raw_connection
    return self._wrap_pool_connect(self.pool.connect, _connection)
  File "/usr/local/lib/python3.6/dist-packages/sqlalchemy/engine/base.py", line 3254, in _wrap_pool_connect
    e, dialect, self
  File "/usr/local/lib/python3.6/dist-packages/sqlalchemy/engine/base.py", line 2101, in _handle_dbapi_exception_noconnection
    sqlalchemy_exception, with_traceback=exc_info[2], from_=e
  File "/usr/local/lib/python3.6/dist-packages/sqlalchemy/util/compat.py", line 207, in raise_
    raise exception
  File "/usr/local/lib/python3.6/dist-packages/sqlalchemy/engine/base.py", line 3250, in _wrap_pool_connect
    return fn()
  File "/usr/local/lib/python3.6/dist-packages/sqlalchemy/pool/base.py", line 310, in connect
    return _ConnectionFairy._checkout(self)
  File "/usr/local/lib/python3.6/dist-packages/sqlalchemy/pool/base.py", line 868, in _checkout
    fairy = _ConnectionRecord.checkout(pool)
  File "/usr/local/lib/python3.6/dist-packages/sqlalchemy/pool/base.py", line 476, in checkout
    rec = pool._do_get()
  File "/usr/local/lib/python3.6/dist-packages/sqlalchemy/pool/impl.py", line 146, in _do_get
    self._dec_overflow()
  File "/usr/local/lib/python3.6/dist-packages/sqlalchemy/util/langhelpers.py", line 72, in __exit__
    with_traceback=exc_tb,
  File "/usr/local/lib/python3.6/dist-packages/sqlalchemy/util/compat.py", line 207, in raise_
    raise exception
  File "/usr/local/lib/python3.6/dist-packages/sqlalchemy/pool/impl.py", line 143, in _do_get
    return self._create_connection()
  File "/usr/local/lib/python3.6/dist-packages/sqlalchemy/pool/base.py", line 256, in _create_connection
    return _ConnectionRecord(self)
  File "/usr/local/lib/python3.6/dist-packages/sqlalchemy/pool/base.py", line 371, in __init__
    self.__connect()
  File "/usr/local/lib/python3.6/dist-packages/sqlalchemy/pool/base.py", line 666, in __connect
    pool.logger.debug("Error on connect(): %s", e)
  File "/usr/local/lib/python3.6/dist-packages/sqlalchemy/util/langhelpers.py", line 72, in __exit__
    with_traceback=exc_tb,
  File "/usr/local/lib/python3.6/dist-packages/sqlalchemy/util/compat.py", line 207, in raise_
    raise exception
  File "/usr/local/lib/python3.6/dist-packages/sqlalchemy/pool/base.py", line 661, in __connect
    self.dbapi_connection = connection = pool._invoke_creator(self)
  File "/usr/local/lib/python3.6/dist-packages/sqlalchemy/engine/create.py", line 590, in connect
    return dialect.connect(*cargs, **cparams)
  File "/usr/local/lib/python3.6/dist-packages/sqlalchemy/engine/default.py", line 597, in connect
    return self.dbapi.connect(*cargs, **cparams)
  File "/usr/local/lib/python3.6/dist-packages/psycopg2/__init__.py", line 122, in connect
    conn = _connect(dsn, connection_factory=connection_factory, **kwasync)
sqlalchemy.exc.OperationalError: (psycopg2.OperationalError) connection to server at "localhost" (::1), port 5432 failed: Connection refused
	Is the server running on that host and accepting TCP/IP connections?
connection to server at "localhost" (127.0.0.1), port 5432 failed: Connection refused
	Is the server running on that host and accepting TCP/IP connections?

(Background on this error at: https://sqlalche.me/e/14/e3q8)

Traceback (most recent call last):
  File "/usr/local/lib/python3.6/dist-packages/sqlalchemy/engine/base.py", line 3250, in _wrap_pool_connect
    return fn()
  File "/usr/local/lib/python3.6/dist-packages/sqlalchemy/pool/base.py", line 310, in connect
    return _ConnectionFairy._checkout(self)
  File "/usr/local/lib/python3.6/dist-packages/sqlalchemy/pool/base.py", line 868, in _checkout
    fairy = _ConnectionRecord.checkout(pool)
  File "/usr/local/lib/python3.6/dist-packages/sqlalchemy/pool/base.py", line 476, in checkout
    rec = pool._do_get()
  File "/usr/local/lib/python3.6/dist-packages/sqlalchemy/pool/impl.py", line 146, in _do_get
    self._dec_overflow()
  File "/usr/local/lib/python3.6/dist-packages/sqlalchemy/util/langhelpers.py", line 72, in __exit__
    with_traceback=exc_tb,
  File "/usr/local/lib/python3.6/dist-packages/sqlalchemy/util/compat.py", line 207, in raise_
    raise exception
  File "/usr/local/lib/python3.6/dist-packages/sqlalchemy/pool/impl.py", line 143, in _do_get
    return self._create_connection()
  File "/usr/local/lib/python3.6/dist-packages/sqlalchemy/pool/base.py", line 256, in _create_connection
    return _ConnectionRecord(self)
  File "/usr/local/lib/python3.6/dist-packages/sqlalchemy/pool/base.py", line 371, in __init__
    self.__connect()
  File "/usr/local/lib/python3.6/dist-packages/sqlalchemy/pool/base.py", line 666, in __connect
    pool.logger.debug("Error on connect(): %s", e)
  File "/usr/local/lib/python3.6/dist-packages/sqlalchemy/util/langhelpers.py", line 72, in __exit__
    with_traceback=exc_tb,
  File "/usr/local/lib/python3.6/dist-packages/sqlalchemy/util/compat.py", line 207, in raise_
    raise exception
  File "/usr/local/lib/python3.6/dist-packages/sqlalchemy/pool/base.py", line 661, in __connect
    self.dbapi_connection = connection = pool._invoke_creator(self)
  File "/usr/local/lib/python3.6/dist-packages/sqlalchemy/engine/create.py", line 590, in connect
    return dialect.connect(*cargs, **cparams)
  File "/usr/local/lib/python3.6/dist-packages/sqlalchemy/engine/default.py", line 597, in connect
    return self.dbapi.connect(*cargs, **cparams)
  File "/usr/local/lib/python3.6/dist-packages/psycopg2/__init__.py", line 122, in connect
    conn = _connect(dsn, connection_factory=connection_factory, **kwasync)
psycopg2.OperationalError: connection to server at "localhost" (::1), port 5432 failed: Connection refused
	Is the server running on that host and accepting TCP/IP connections?
connection to server at "localhost" (127.0.0.1), port 5432 failed: Connection refused
	Is the server running on that host and accepting TCP/IP connections?


The above exception was the direct cause of the following exception:

Traceback (most recent call last):
  File "/tmp/tmp.d9lusb0FGf/orchestra/orchestra/parsers/PilotParser.py", line 73, in run
    pilot.init()
  File "/tmp/tmp.d9lusb0FGf/orchestra/orchestra/Pilot.py", line 54, in init
    self.__devices.init()
  File "/tmp/tmp.d9lusb0FGf/orchestra/orchestra/core/Devices.py", line 34, in init
    for device in self.__db.session().query(Device).filter(Device.nodename==self.nodename).all():
  File "/usr/local/lib/python3.6/dist-packages/sqlalchemy/orm/query.py", line 2759, in all
    return self._iter().all()
  File "/usr/local/lib/python3.6/dist-packages/sqlalchemy/orm/query.py", line 2897, in _iter
    execution_options={"_sa_orm_load_options": self.load_options},
  File "/usr/local/lib/python3.6/dist-packages/sqlalchemy/orm/session.py", line 1691, in execute
    conn = self._connection_for_bind(bind)
  File "/usr/local/lib/python3.6/dist-packages/sqlalchemy/orm/session.py", line 1533, in _connection_for_bind
    engine, execution_options
  File "/usr/local/lib/python3.6/dist-packages/sqlalchemy/orm/session.py", line 747, in _connection_for_bind
    conn = bind.connect()
  File "/usr/local/lib/python3.6/dist-packages/sqlalchemy/engine/base.py", line 3204, in connect
    return self._connection_cls(self, close_with_result=close_with_result)
  File "/usr/local/lib/python3.6/dist-packages/sqlalchemy/engine/base.py", line 96, in __init__
    else engine.raw_connection()
  File "/usr/local/lib/python3.6/dist-packages/sqlalchemy/engine/base.py", line 3283, in raw_connection
    return self._wrap_pool_connect(self.pool.connect, _connection)
  File "/usr/local/lib/python3.6/dist-packages/sqlalchemy/engine/base.py", line 3254, in _wrap_pool_connect
    e, dialect, self
  File "/usr/local/lib/python3.6/dist-packages/sqlalchemy/engine/base.py", line 2101, in _handle_dbapi_exception_noconnection
    sqlalchemy_exception, with_traceback=exc_info[2], from_=e
  File "/usr/local/lib/python3.6/dist-packages/sqlalchemy/util/compat.py", line 207, in raise_
    raise exception
  File "/usr/local/lib/python3.6/dist-packages/sqlalchemy/engine/base.py", line 3250, in _wrap_pool_connect
    return fn()
  File "/usr/local/lib/python3.6/dist-packages/sqlalchemy/pool/base.py", line 310, in connect
    return _ConnectionFairy._checkout(self)
  File "/usr/local/lib/python3.6/dist-packages/sqlalchemy/pool/base.py", line 868, in _checkout
    fairy = _ConnectionRecord.checkout(pool)
  File "/usr/local/lib/python3.6/dist-packages/sqlalchemy/pool/base.py", line 476, in checkout
    rec = pool._do_get()
  File "/usr/local/lib/python3.6/dist-packages/sqlalchemy/pool/impl.py", line 146, in _do_get
    self._dec_overflow()
  File "/usr/local/lib/python3.6/dist-packages/sqlalchemy/util/langhelpers.py", line 72, in __exit__
    with_traceback=exc_tb,
  File "/usr/local/lib/python3.6/dist-packages/sqlalchemy/util/compat.py", line 207, in raise_
    raise exception
  File "/usr/local/lib/python3.6/dist-packages/sqlalchemy/pool/impl.py", line 143, in _do_get
    return self._create_connection()
  File "/usr/local/lib/python3.6/dist-packages/sqlalchemy/pool/base.py", line 256, in _create_connection
    return _ConnectionRecord(self)
  File "/usr/local/lib/python3.6/dist-packages/sqlalchemy/pool/base.py", line 371, in __init__
    self.__connect()
  File "/usr/local/lib/python3.6/dist-packages/sqlalchemy/pool/base.py", line 666, in __connect
    pool.logger.debug("Error on connect(): %s", e)
  File "/usr/local/lib/python3.6/dist-packages/sqlalchemy/util/langhelpers.py", line 72, in __exit__
    with_traceback=exc_tb,
  File "/usr/local/lib/python3.6/dist-packages/sqlalchemy/util/compat.py", line 207, in raise_
    raise exception
  File "/usr/local/lib/python3.6/dist-packages/sqlalchemy/pool/base.py", line 661, in __connect
    self.dbapi_connection = connection = pool._invoke_creator(self)
  File "/usr/local/lib/python3.6/dist-packages/sqlalchemy/engine/create.py", line 590, in connect
    return dialect.connect(*cargs, **cparams)
  File "/usr/local/lib/python3.6/dist-packages/sqlalchemy/engine/default.py", line 597, in connect
    return self.dbapi.connect(*cargs, **cparams)
  File "/usr/local/lib/python3.6/dist-packages/psycopg2/__init__.py", line 122, in connect
    conn = _connect(dsn, connection_factory=connection_factory, **kwasync)
sqlalchemy.exc.OperationalError: (psycopg2.OperationalError) connection to server at "localhost" (::1), port 5432 failed: Connection refused
	Is the server running on that host and accepting TCP/IP connections?
connection to server at "localhost" (127.0.0.1), port 5432 failed: Connection refused
	Is the server running on that host and accepting TCP/IP connections?

(Background on this error at: https://sqlalche.me/e/14/e3q8)
Traceback (most recent call last):
  File "/usr/local/lib/python3.6/dist-packages/sqlalchemy/engine/base.py", line 3250, in _wrap_pool_connect
    return fn()
  File "/usr/local/lib/python3.6/dist-packages/sqlalchemy/pool/base.py", line 310, in connect
    return _ConnectionFairy._checkout(self)
  File "/usr/local/lib/python3.6/dist-packages/sqlalchemy/pool/base.py", line 868, in _checkout
    fairy = _ConnectionRecord.checkout(pool)
  File "/usr/local/lib/python3.6/dist-packages/sqlalchemy/pool/base.py", line 476, in checkout
    rec = pool._do_get()
  File "/usr/local/lib/python3.6/dist-packages/sqlalchemy/pool/impl.py", line 146, in _do_get
    self._dec_overflow()
  File "/usr/local/lib/python3.6/dist-packages/sqlalchemy/util/langhelpers.py", line 72, in __exit__
    with_traceback=exc_tb,
  File "/usr/local/lib/python3.6/dist-packages/sqlalchemy/util/compat.py", line 207, in raise_
    raise exception
  File "/usr/local/lib/python3.6/dist-packages/sqlalchemy/pool/impl.py", line 143, in _do_get
    return self._create_connection()
  File "/usr/local/lib/python3.6/dist-packages/sqlalchemy/pool/base.py", line 256, in _create_connection
    return _ConnectionRecord(self)
  File "/usr/local/lib/python3.6/dist-packages/sqlalchemy/pool/base.py", line 371, in __init__
    self.__connect()
  File "/usr/local/lib/python3.6/dist-packages/sqlalchemy/pool/base.py", line 666, in __connect
    pool.logger.debug("Error on connect(): %s", e)
  File "/usr/local/lib/python3.6/dist-packages/sqlalchemy/util/langhelpers.py", line 72, in __exit__
    with_traceback=exc_tb,
  File "/usr/local/lib/python3.6/dist-packages/sqlalchemy/util/compat.py", line 207, in raise_
    raise exception
  File "/usr/local/lib/python3.6/dist-packages/sqlalchemy/pool/base.py", line 661, in __connect
    self.dbapi_connection = connection = pool._invoke_creator(self)
  File "/usr/local/lib/python3.6/dist-packages/sqlalchemy/engine/create.py", line 590, in connect
    return dialect.connect(*cargs, **cparams)
  File "/usr/local/lib/python3.6/dist-packages/sqlalchemy/engine/default.py", line 597, in connect
    return self.dbapi.connect(*cargs, **cparams)
  File "/usr/local/lib/python3.6/dist-packages/psycopg2/__init__.py", line 122, in connect
    conn = _connect(dsn, connection_factory=connection_factory, **kwasync)
psycopg2.OperationalError: connection to server at "localhost" (::1), port 5432 failed: Connection refused
	Is the server running on that host and accepting TCP/IP connections?
connection to server at "localhost" (127.0.0.1), port 5432 failed: Connection refused
	Is the server running on that host and accepting TCP/IP connections?


The above exception was the direct cause of the following exception:

Traceback (most recent call last):
  File "/tmp/tmp.d9lusb0FGf/orchestra/orchestra/parsers/PilotParser.py", line 73, in run
    pilot.init()
  File "/tmp/tmp.d9lusb0FGf/orchestra/orchestra/Pilot.py", line 54, in init
    self.__devices.init()
  File "/tmp/tmp.d9lusb0FGf/orchestra/orchestra/core/Devices.py", line 34, in init
    for device in self.__db.session().query(Device).filter(Device.nodename==self.nodename).all():
  File "/usr/local/lib/python3.6/dist-packages/sqlalchemy/orm/query.py", line 2759, in all
    return self._iter().all()
  File "/usr/local/lib/python3.6/dist-packages/sqlalchemy/orm/query.py", line 2897, in _iter
    execution_options={"_sa_orm_load_options": self.load_options},
  File "/usr/local/lib/python3.6/dist-packages/sqlalchemy/orm/session.py", line 1691, in execute
    conn = self._connection_for_bind(bind)
  File "/usr/local/lib/python3.6/dist-packages/sqlalchemy/orm/session.py", line 1533, in _connection_for_bind
    engine, execution_options
  File "/usr/local/lib/python3.6/dist-packages/sqlalchemy/orm/session.py", line 747, in _connection_for_bind
    conn = bind.connect()
  File "/usr/local/lib/python3.6/dist-packages/sqlalchemy/engine/base.py", line 3204, in connect
    return self._connection_cls(self, close_with_result=close_with_result)
  File "/usr/local/lib/python3.6/dist-packages/sqlalchemy/engine/base.py", line 96, in __init__
    else engine.raw_connection()
  File "/usr/local/lib/python3.6/dist-packages/sqlalchemy/engine/base.py", line 3283, in raw_connection
    return self._wrap_pool_connect(self.pool.connect, _connection)
  File "/usr/local/lib/python3.6/dist-packages/sqlalchemy/engine/base.py", line 3254, in _wrap_pool_connect
    e, dialect, self
  File "/usr/local/lib/python3.6/dist-packages/sqlalchemy/engine/base.py", line 2101, in _handle_dbapi_exception_noconnection
    sqlalchemy_exception, with_traceback=exc_info[2], from_=e
  File "/usr/local/lib/python3.6/dist-packages/sqlalchemy/util/compat.py", line 207, in raise_
    raise exception
  File "/usr/local/lib/python3.6/dist-packages/sqlalchemy/engine/base.py", line 3250, in _wrap_pool_connect
    return fn()
  File "/usr/local/lib/python3.6/dist-packages/sqlalchemy/pool/base.py", line 310, in connect
    return _ConnectionFairy._checkout(self)
  File "/usr/local/lib/python3.6/dist-packages/sqlalchemy/pool/base.py", line 868, in _checkout
    fairy = _ConnectionRecord.checkout(pool)
  File "/usr/local/lib/python3.6/dist-packages/sqlalchemy/pool/base.py", line 476, in checkout
    rec = pool._do_get()
  File "/usr/local/lib/python3.6/dist-packages/sqlalchemy/pool/impl.py", line 146, in _do_get
    self._dec_overflow()
  File "/usr/local/lib/python3.6/dist-packages/sqlalchemy/util/langhelpers.py", line 72, in __exit__
    with_traceback=exc_tb,
  File "/usr/local/lib/python3.6/dist-packages/sqlalchemy/util/compat.py", line 207, in raise_
    raise exception
  File "/usr/local/lib/python3.6/dist-packages/sqlalchemy/pool/impl.py", line 143, in _do_get
    return self._create_connection()
  File "/usr/local/lib/python3.6/dist-packages/sqlalchemy/pool/base.py", line 256, in _create_connection
    return _ConnectionRecord(self)
  File "/usr/local/lib/python3.6/dist-packages/sqlalchemy/pool/base.py", line 371, in __init__
    self.__connect()
  File "/usr/local/lib/python3.6/dist-packages/sqlalchemy/pool/base.py", line 666, in __connect
    pool.logger.debug("Error on connect(): %s", e)
  File "/usr/local/lib/python3.6/dist-packages/sqlalchemy/util/langhelpers.py", line 72, in __exit__
    with_traceback=exc_tb,
  File "/usr/local/lib/python3.6/dist-packages/sqlalchemy/util/compat.py", line 207, in raise_
    raise exception
  File "/usr/local/lib/python3.6/dist-packages/sqlalchemy/pool/base.py", line 661, in __connect
    self.dbapi_connection = connection = pool._invoke_creator(self)
  File "/usr/local/lib/python3.6/dist-packages/sqlalchemy/engine/create.py", line 590, in connect
    return dialect.connect(*cargs, **cparams)
  File "/usr/local/lib/python3.6/dist-packages/sqlalchemy/engine/default.py", line 597, in connect
    return self.dbapi.connect(*cargs, **cparams)
  File "/usr/local/lib/python3.6/dist-packages/psycopg2/__init__.py", line 122, in connect
    conn = _connect(dsn, connection_factory=connection_factory, **kwasync)
sqlalchemy.exc.OperationalError: (psycopg2.OperationalError) connection to server at "localhost" (::1), port 5432 failed: Connection refused
	Is the server running on that host and accepting TCP/IP connections?
connection to server at "localhost" (127.0.0.1), port 5432 failed: Connection refused
	Is the server running on that host and accepting TCP/IP connections?

(Background on this error at: https://sqlalche.me/e/14/e3q8)

During handling of the above exception, another exception occurred:

Traceback (most recent call last):
  File "/tmp/tmp.d9lusb0FGf/orchestra/orchestra/mailing/Postman.py", line 45, in __send
    server.login(self.__myEmail, self.__myPassword)
  File "/usr/lib/python3.6/smtplib.py", line 721, in login
    initial_response_ok=initial_response_ok)
  File "/usr/lib/python3.6/smtplib.py", line 631, in auth
    (code, resp) = self.docmd("AUTH", mechanism + " " + response)
  File "/usr/lib/python3.6/smtplib.py", line 421, in docmd
    return self.getreply()
  File "/usr/lib/python3.6/smtplib.py", line 394, in getreply
    raise SMTPServerDisconnected("Connection unexpectedly closed")
smtplib.SMTPServerDisconnected: Connection unexpectedly closed
Traceback (most recent call last):
  File "/usr/local/lib/python3.6/dist-packages/sqlalchemy/engine/base.py", line 3250, in _wrap_pool_connect
    return fn()
  File "/usr/local/lib/python3.6/dist-packages/sqlalchemy/pool/base.py", line 310, in connect
    return _ConnectionFairy._checkout(self)
  File "/usr/local/lib/python3.6/dist-packages/sqlalchemy/pool/base.py", line 868, in _checkout
    fairy = _ConnectionRecord.checkout(pool)
  File "/usr/local/lib/python3.6/dist-packages/sqlalchemy/pool/base.py", line 476, in checkout
    rec = pool._do_get()
  File "/usr/local/lib/python3.6/dist-packages/sqlalchemy/pool/impl.py", line 146, in _do_get
    self._dec_overflow()
  File "/usr/local/lib/python3.6/dist-packages/sqlalchemy/util/langhelpers.py", line 72, in __exit__
    with_traceback=exc_tb,
  File "/usr/local/lib/python3.6/dist-packages/sqlalchemy/util/compat.py", line 207, in raise_
    raise exception
  File "/usr/local/lib/python3.6/dist-packages/sqlalchemy/pool/impl.py", line 143, in _do_get
    return self._create_connection()
  File "/usr/local/lib/python3.6/dist-packages/sqlalchemy/pool/base.py", line 256, in _create_connection
    return _ConnectionRecord(self)
  File "/usr/local/lib/python3.6/dist-packages/sqlalchemy/pool/base.py", line 371, in __init__
    self.__connect()
  File "/usr/local/lib/python3.6/dist-packages/sqlalchemy/pool/base.py", line 666, in __connect
    pool.logger.debug("Error on connect(): %s", e)
  File "/usr/local/lib/python3.6/dist-packages/sqlalchemy/util/langhelpers.py", line 72, in __exit__
    with_traceback=exc_tb,
  File "/usr/local/lib/python3.6/dist-packages/sqlalchemy/util/compat.py", line 207, in raise_
    raise exception
  File "/usr/local/lib/python3.6/dist-packages/sqlalchemy/pool/base.py", line 661, in __connect
    self.dbapi_connection = connection = pool._invoke_creator(self)
  File "/usr/local/lib/python3.6/dist-packages/sqlalchemy/engine/create.py", line 590, in connect
    return dialect.connect(*cargs, **cparams)
  File "/usr/local/lib/python3.6/dist-packages/sqlalchemy/engine/default.py", line 597, in connect
    return self.dbapi.connect(*cargs, **cparams)
  File "/usr/local/lib/python3.6/dist-packages/psycopg2/__init__.py", line 122, in connect
    conn = _connect(dsn, connection_factory=connection_factory, **kwasync)
psycopg2.OperationalError: connection to server at "localhost" (::1), port 5432 failed: Connection refused
	Is the server running on that host and accepting TCP/IP connections?
connection to server at "localhost" (127.0.0.1), port 5432 failed: Connection refused
	Is the server running on that host and accepting TCP/IP connections?


The above exception was the direct cause of the following exception:

Traceback (most recent call last):
  File "/tmp/tmp.d9lusb0FGf/orchestra/orchestra/parsers/PilotParser.py", line 73, in run
    pilot.init()
  File "/tmp/tmp.d9lusb0FGf/orchestra/orchestra/Pilot.py", line 54, in init
    self.__devices.init()
  File "/tmp/tmp.d9lusb0FGf/orchestra/orchestra/core/Devices.py", line 34, in init
    for device in self.__db.session().query(Device).filter(Device.nodename==self.nodename).all():
  File "/usr/local/lib/python3.6/dist-packages/sqlalchemy/orm/query.py", line 2759, in all
    return self._iter().all()
  File "/usr/local/lib/python3.6/dist-packages/sqlalchemy/orm/query.py", line 2897, in _iter
    execution_options={"_sa_orm_load_options": self.load_options},
  File "/usr/local/lib/python3.6/dist-packages/sqlalchemy/orm/session.py", line 1691, in execute
    conn = self._connection_for_bind(bind)
  File "/usr/local/lib/python3.6/dist-packages/sqlalchemy/orm/session.py", line 1533, in _connection_for_bind
    engine, execution_options
  File "/usr/local/lib/python3.6/dist-packages/sqlalchemy/orm/session.py", line 747, in _connection_for_bind
    conn = bind.connect()
  File "/usr/local/lib/python3.6/dist-packages/sqlalchemy/engine/base.py", line 3204, in connect
    return self._connection_cls(self, close_with_result=close_with_result)
  File "/usr/local/lib/python3.6/dist-packages/sqlalchemy/engine/base.py", line 96, in __init__
    else engine.raw_connection()
  File "/usr/local/lib/python3.6/dist-packages/sqlalchemy/engine/base.py", line 3283, in raw_connection
    return self._wrap_pool_connect(self.pool.connect, _connection)
  File "/usr/local/lib/python3.6/dist-packages/sqlalchemy/engine/base.py", line 3254, in _wrap_pool_connect
    e, dialect, self
  File "/usr/local/lib/python3.6/dist-packages/sqlalchemy/engine/base.py", line 2101, in _handle_dbapi_exception_noconnection
    sqlalchemy_exception, with_traceback=exc_info[2], from_=e
  File "/usr/local/lib/python3.6/dist-packages/sqlalchemy/util/compat.py", line 207, in raise_
    raise exception
  File "/usr/local/lib/python3.6/dist-packages/sqlalchemy/engine/base.py", line 3250, in _wrap_pool_connect
    return fn()
  File "/usr/local/lib/python3.6/dist-packages/sqlalchemy/pool/base.py", line 310, in connect
    return _ConnectionFairy._checkout(self)
  File "/usr/local/lib/python3.6/dist-packages/sqlalchemy/pool/base.py", line 868, in _checkout
    fairy = _ConnectionRecord.checkout(pool)
  File "/usr/local/lib/python3.6/dist-packages/sqlalchemy/pool/base.py", line 476, in checkout
    rec = pool._do_get()
  File "/usr/local/lib/python3.6/dist-packages/sqlalchemy/pool/impl.py", line 146, in _do_get
    self._dec_overflow()
  File "/usr/local/lib/python3.6/dist-packages/sqlalchemy/util/langhelpers.py", line 72, in __exit__
    with_traceback=exc_tb,
  File "/usr/local/lib/python3.6/dist-packages/sqlalchemy/util/compat.py", line 207, in raise_
    raise exception
  File "/usr/local/lib/python3.6/dist-packages/sqlalchemy/pool/impl.py", line 143, in _do_get
    return self._create_connection()
  File "/usr/local/lib/python3.6/dist-packages/sqlalchemy/pool/base.py", line 256, in _create_connection
    return _ConnectionRecord(self)
  File "/usr/local/lib/python3.6/dist-packages/sqlalchemy/pool/base.py", line 371, in __init__
    self.__connect()
  File "/usr/local/lib/python3.6/dist-packages/sqlalchemy/pool/base.py", line 666, in __connect
    pool.logger.debug("Error on connect(): %s", e)
  File "/usr/local/lib/python3.6/dist-packages/sqlalchemy/util/langhelpers.py", line 72, in __exit__
    with_traceback=exc_tb,
  File "/usr/local/lib/python3.6/dist-packages/sqlalchemy/util/compat.py", line 207, in raise_
    raise exception
  File "/usr/local/lib/python3.6/dist-packages/sqlalchemy/pool/base.py", line 661, in __connect
    self.dbapi_connection = connection = pool._invoke_creator(self)
  File "/usr/local/lib/python3.6/dist-packages/sqlalchemy/engine/create.py", line 590, in connect
    return dialect.connect(*cargs, **cparams)
  File "/usr/local/lib/python3.6/dist-packages/sqlalchemy/engine/default.py", line 597, in connect
    return self.dbapi.connect(*cargs, **cparams)
  File "/usr/local/lib/python3.6/dist-packages/psycopg2/__init__.py", line 122, in connect
    conn = _connect(dsn, connection_factory=connection_factory, **kwasync)
sqlalchemy.exc.OperationalError: (psycopg2.OperationalError) connection to server at "localhost" (::1), port 5432 failed: Connection refused
	Is the server running on that host and accepting TCP/IP connections?
connection to server at "localhost" (127.0.0.1), port 5432 failed: Connection refused
	Is the server running on that host and accepting TCP/IP connections?

(Background on this error at: https://sqlalche.me/e/14/e3q8)

Traceback (most recent call last):
  File "/usr/local/lib/python3.6/dist-packages/sqlalchemy/engine/base.py", line 3250, in _wrap_pool_connect
    return fn()
  File "/usr/local/lib/python3.6/dist-packages/sqlalchemy/pool/base.py", line 310, in connect
    return _ConnectionFairy._checkout(self)
  File "/usr/local/lib/python3.6/dist-packages/sqlalchemy/pool/base.py", line 868, in _checkout
    fairy = _ConnectionRecord.checkout(pool)
  File "/usr/local/lib/python3.6/dist-packages/sqlalchemy/pool/base.py", line 476, in checkout
    rec = pool._do_get()
  File "/usr/local/lib/python3.6/dist-packages/sqlalchemy/pool/impl.py", line 146, in _do_get
    self._dec_overflow()
  File "/usr/local/lib/python3.6/dist-packages/sqlalchemy/util/langhelpers.py", line 72, in __exit__
    with_traceback=exc_tb,
  File "/usr/local/lib/python3.6/dist-packages/sqlalchemy/util/compat.py", line 207, in raise_
    raise exception
  File "/usr/local/lib/python3.6/dist-packages/sqlalchemy/pool/impl.py", line 143, in _do_get
    return self._create_connection()
  File "/usr/local/lib/python3.6/dist-packages/sqlalchemy/pool/base.py", line 256, in _create_connection
    return _ConnectionRecord(self)
  File "/usr/local/lib/python3.6/dist-packages/sqlalchemy/pool/base.py", line 371, in __init__
    self.__connect()
  File "/usr/local/lib/python3.6/dist-packages/sqlalchemy/pool/base.py", line 666, in __connect
    pool.logger.debug("Error on connect(): %s", e)
  File "/usr/local/lib/python3.6/dist-packages/sqlalchemy/util/langhelpers.py", line 72, in __exit__
    with_traceback=exc_tb,
  File "/usr/local/lib/python3.6/dist-packages/sqlalchemy/util/compat.py", line 207, in raise_
    raise exception
  File "/usr/local/lib/python3.6/dist-packages/sqlalchemy/pool/base.py", line 661, in __connect
    self.dbapi_connection = connection = pool._invoke_creator(self)
  File "/usr/local/lib/python3.6/dist-packages/sqlalchemy/engine/create.py", line 590, in connect
    return dialect.connect(*cargs, **cparams)
  File "/usr/local/lib/python3.6/dist-packages/sqlalchemy/engine/default.py", line 597, in connect
    return self.dbapi.connect(*cargs, **cparams)
  File "/usr/local/lib/python3.6/dist-packages/psycopg2/__init__.py", line 122, in connect
    conn = _connect(dsn, connection_factory=connection_factory, **kwasync)
psycopg2.OperationalError: connection to server at "localhost" (::1), port 5432 failed: Connection refused
	Is the server running on that host and accepting TCP/IP connections?
connection to server at "localhost" (127.0.0.1), port 5432 failed: Connection refused
	Is the server running on that host and accepting TCP/IP connections?


The above exception was the direct cause of the following exception:

Traceback (most recent call last):
  File "/tmp/tmp.d9lusb0FGf/orchestra/orchestra/parsers/PilotParser.py", line 73, in run
    pilot.init()
  File "/tmp/tmp.d9lusb0FGf/orchestra/orchestra/Pilot.py", line 54, in init
    self.__devices.init()
  File "/tmp/tmp.d9lusb0FGf/orchestra/orchestra/core/Devices.py", line 34, in init
    for device in self.__db.session().query(Device).filter(Device.nodename==self.nodename).all():
  File "/usr/local/lib/python3.6/dist-packages/sqlalchemy/orm/query.py", line 2759, in all
    return self._iter().all()
  File "/usr/local/lib/python3.6/dist-packages/sqlalchemy/orm/query.py", line 2897, in _iter
    execution_options={"_sa_orm_load_options": self.load_options},
  File "/usr/local/lib/python3.6/dist-packages/sqlalchemy/orm/session.py", line 1691, in execute
    conn = self._connection_for_bind(bind)
  File "/usr/local/lib/python3.6/dist-packages/sqlalchemy/orm/session.py", line 1533, in _connection_for_bind
    engine, execution_options
  File "/usr/local/lib/python3.6/dist-packages/sqlalchemy/orm/session.py", line 747, in _connection_for_bind
    conn = bind.connect()
  File "/usr/local/lib/python3.6/dist-packages/sqlalchemy/engine/base.py", line 3204, in connect
    return self._connection_cls(self, close_with_result=close_with_result)
  File "/usr/local/lib/python3.6/dist-packages/sqlalchemy/engine/base.py", line 96, in __init__
    else engine.raw_connection()
  File "/usr/local/lib/python3.6/dist-packages/sqlalchemy/engine/base.py", line 3283, in raw_connection
    return self._wrap_pool_connect(self.pool.connect, _connection)
  File "/usr/local/lib/python3.6/dist-packages/sqlalchemy/engine/base.py", line 3254, in _wrap_pool_connect
    e, dialect, self
  File "/usr/local/lib/python3.6/dist-packages/sqlalchemy/engine/base.py", line 2101, in _handle_dbapi_exception_noconnection
    sqlalchemy_exception, with_traceback=exc_info[2], from_=e
  File "/usr/local/lib/python3.6/dist-packages/sqlalchemy/util/compat.py", line 207, in raise_
    raise exception
  File "/usr/local/lib/python3.6/dist-packages/sqlalchemy/engine/base.py", line 3250, in _wrap_pool_connect
    return fn()
  File "/usr/local/lib/python3.6/dist-packages/sqlalchemy/pool/base.py", line 310, in connect
    return _ConnectionFairy._checkout(self)
  File "/usr/local/lib/python3.6/dist-packages/sqlalchemy/pool/base.py", line 868, in _checkout
    fairy = _ConnectionRecord.checkout(pool)
  File "/usr/local/lib/python3.6/dist-packages/sqlalchemy/pool/base.py", line 476, in checkout
    rec = pool._do_get()
  File "/usr/local/lib/python3.6/dist-packages/sqlalchemy/pool/impl.py", line 146, in _do_get
    self._dec_overflow()
  File "/usr/local/lib/python3.6/dist-packages/sqlalchemy/util/langhelpers.py", line 72, in __exit__
    with_traceback=exc_tb,
  File "/usr/local/lib/python3.6/dist-packages/sqlalchemy/util/compat.py", line 207, in raise_
    raise exception
  File "/usr/local/lib/python3.6/dist-packages/sqlalchemy/pool/impl.py", line 143, in _do_get
    return self._create_connection()
  File "/usr/local/lib/python3.6/dist-packages/sqlalchemy/pool/base.py", line 256, in _create_connection
    return _ConnectionRecord(self)
  File "/usr/local/lib/python3.6/dist-packages/sqlalchemy/pool/base.py", line 371, in __init__
    self.__connect()
  File "/usr/local/lib/python3.6/dist-packages/sqlalchemy/pool/base.py", line 666, in __connect
    pool.logger.debug("Error on connect(): %s", e)
  File "/usr/local/lib/python3.6/dist-packages/sqlalchemy/util/langhelpers.py", line 72, in __exit__
    with_traceback=exc_tb,
  File "/usr/local/lib/python3.6/dist-packages/sqlalchemy/util/compat.py", line 207, in raise_
    raise exception
  File "/usr/local/lib/python3.6/dist-packages/sqlalchemy/pool/base.py", line 661, in __connect
    self.dbapi_connection = connection = pool._invoke_creator(self)
  File "/usr/local/lib/python3.6/dist-packages/sqlalchemy/engine/create.py", line 590, in connect
    return dialect.connect(*cargs, **cparams)
  File "/usr/local/lib/python3.6/dist-packages/sqlalchemy/engine/default.py", line 597, in connect
    return self.dbapi.connect(*cargs, **cparams)
  File "/usr/local/lib/python3.6/dist-packages/psycopg2/__init__.py", line 122, in connect
    conn = _connect(dsn, connection_factory=connection_factory, **kwasync)
sqlalchemy.exc.OperationalError: (psycopg2.OperationalError) connection to server at "localhost" (::1), port 5432 failed: Connection refused
	Is the server running on that host and accepting TCP/IP connections?
connection to server at "localhost" (127.0.0.1), port 5432 failed: Connection refused
	Is the server running on that host and accepting TCP/IP connections?

(Background on this error at: https://sqlalche.me/e/14/e3q8)
Traceback (most recent call last):
  File "/usr/local/lib/python3.6/dist-packages/sqlalchemy/engine/base.py", line 3250, in _wrap_pool_connect
    return fn()
  File "/usr/local/lib/python3.6/dist-packages/sqlalchemy/pool/base.py", line 310, in connect
    return _ConnectionFairy._checkout(self)
  File "/usr/local/lib/python3.6/dist-packages/sqlalchemy/pool/base.py", line 868, in _checkout
    fairy = _ConnectionRecord.checkout(pool)
  File "/usr/local/lib/python3.6/dist-packages/sqlalchemy/pool/base.py", line 476, in checkout
    rec = pool._do_get()
  File "/usr/local/lib/python3.6/dist-packages/sqlalchemy/pool/impl.py", line 146, in _do_get
    self._dec_overflow()
  File "/usr/local/lib/python3.6/dist-packages/sqlalchemy/util/langhelpers.py", line 72, in __exit__
    with_traceback=exc_tb,
  File "/usr/local/lib/python3.6/dist-packages/sqlalchemy/util/compat.py", line 207, in raise_
    raise exception
  File "/usr/local/lib/python3.6/dist-packages/sqlalchemy/pool/impl.py", line 143, in _do_get
    return self._create_connection()
  File "/usr/local/lib/python3.6/dist-packages/sqlalchemy/pool/base.py", line 256, in _create_connection
    return _ConnectionRecord(self)
  File "/usr/local/lib/python3.6/dist-packages/sqlalchemy/pool/base.py", line 371, in __init__
    self.__connect()
  File "/usr/local/lib/python3.6/dist-packages/sqlalchemy/pool/base.py", line 666, in __connect
    pool.logger.debug("Error on connect(): %s", e)
  File "/usr/local/lib/python3.6/dist-packages/sqlalchemy/util/langhelpers.py", line 72, in __exit__
    with_traceback=exc_tb,
  File "/usr/local/lib/python3.6/dist-packages/sqlalchemy/util/compat.py", line 207, in raise_
    raise exception
  File "/usr/local/lib/python3.6/dist-packages/sqlalchemy/pool/base.py", line 661, in __connect
    self.dbapi_connection = connection = pool._invoke_creator(self)
  File "/usr/local/lib/python3.6/dist-packages/sqlalchemy/engine/create.py", line 590, in connect
    return dialect.connect(*cargs, **cparams)
  File "/usr/local/lib/python3.6/dist-packages/sqlalchemy/engine/default.py", line 597, in connect
    return self.dbapi.connect(*cargs, **cparams)
  File "/usr/local/lib/python3.6/dist-packages/psycopg2/__init__.py", line 122, in connect
    conn = _connect(dsn, connection_factory=connection_factory, **kwasync)
psycopg2.OperationalError: connection to server at "localhost" (::1), port 5432 failed: Connection refused
	Is the server running on that host and accepting TCP/IP connections?
connection to server at "localhost" (127.0.0.1), port 5432 failed: Connection refused
	Is the server running on that host and accepting TCP/IP connections?


The above exception was the direct cause of the following exception:

Traceback (most recent call last):
  File "/tmp/tmp.d9lusb0FGf/orchestra/orchestra/parsers/PilotParser.py", line 73, in run
    pilot.init()
  File "/tmp/tmp.d9lusb0FGf/orchestra/orchestra/Pilot.py", line 54, in init
    self.__devices.init()
  File "/tmp/tmp.d9lusb0FGf/orchestra/orchestra/core/Devices.py", line 34, in init
    for device in self.__db.session().query(Device).filter(Device.nodename==self.nodename).all():
  File "/usr/local/lib/python3.6/dist-packages/sqlalchemy/orm/query.py", line 2759, in all
    return self._iter().all()
  File "/usr/local/lib/python3.6/dist-packages/sqlalchemy/orm/query.py", line 2897, in _iter
    execution_options={"_sa_orm_load_options": self.load_options},
  File "/usr/local/lib/python3.6/dist-packages/sqlalchemy/orm/session.py", line 1691, in execute
    conn = self._connection_for_bind(bind)
  File "/usr/local/lib/python3.6/dist-packages/sqlalchemy/orm/session.py", line 1533, in _connection_for_bind
    engine, execution_options
  File "/usr/local/lib/python3.6/dist-packages/sqlalchemy/orm/session.py", line 747, in _connection_for_bind
    conn = bind.connect()
  File "/usr/local/lib/python3.6/dist-packages/sqlalchemy/engine/base.py", line 3204, in connect
    return self._connection_cls(self, close_with_result=close_with_result)
  File "/usr/local/lib/python3.6/dist-packages/sqlalchemy/engine/base.py", line 96, in __init__
    else engine.raw_connection()
  File "/usr/local/lib/python3.6/dist-packages/sqlalchemy/engine/base.py", line 3283, in raw_connection
    return self._wrap_pool_connect(self.pool.connect, _connection)
  File "/usr/local/lib/python3.6/dist-packages/sqlalchemy/engine/base.py", line 3254, in _wrap_pool_connect
    e, dialect, self
  File "/usr/local/lib/python3.6/dist-packages/sqlalchemy/engine/base.py", line 2101, in _handle_dbapi_exception_noconnection
    sqlalchemy_exception, with_traceback=exc_info[2], from_=e
  File "/usr/local/lib/python3.6/dist-packages/sqlalchemy/util/compat.py", line 207, in raise_
    raise exception
  File "/usr/local/lib/python3.6/dist-packages/sqlalchemy/engine/base.py", line 3250, in _wrap_pool_connect
    return fn()
  File "/usr/local/lib/python3.6/dist-packages/sqlalchemy/pool/base.py", line 310, in connect
    return _ConnectionFairy._checkout(self)
  File "/usr/local/lib/python3.6/dist-packages/sqlalchemy/pool/base.py", line 868, in _checkout
    fairy = _ConnectionRecord.checkout(pool)
  File "/usr/local/lib/python3.6/dist-packages/sqlalchemy/pool/base.py", line 476, in checkout
    rec = pool._do_get()
  File "/usr/local/lib/python3.6/dist-packages/sqlalchemy/pool/impl.py", line 146, in _do_get
    self._dec_overflow()
  File "/usr/local/lib/python3.6/dist-packages/sqlalchemy/util/langhelpers.py", line 72, in __exit__
    with_traceback=exc_tb,
  File "/usr/local/lib/python3.6/dist-packages/sqlalchemy/util/compat.py", line 207, in raise_
    raise exception
  File "/usr/local/lib/python3.6/dist-packages/sqlalchemy/pool/impl.py", line 143, in _do_get
    return self._create_connection()
  File "/usr/local/lib/python3.6/dist-packages/sqlalchemy/pool/base.py", line 256, in _create_connection
    return _ConnectionRecord(self)
  File "/usr/local/lib/python3.6/dist-packages/sqlalchemy/pool/base.py", line 371, in __init__
    self.__connect()
  File "/usr/local/lib/python3.6/dist-packages/sqlalchemy/pool/base.py", line 666, in __connect
    pool.logger.debug("Error on connect(): %s", e)
  File "/usr/local/lib/python3.6/dist-packages/sqlalchemy/util/langhelpers.py", line 72, in __exit__
    with_traceback=exc_tb,
  File "/usr/local/lib/python3.6/dist-packages/sqlalchemy/util/compat.py", line 207, in raise_
    raise exception
  File "/usr/local/lib/python3.6/dist-packages/sqlalchemy/pool/base.py", line 661, in __connect
    self.dbapi_connection = connection = pool._invoke_creator(self)
  File "/usr/local/lib/python3.6/dist-packages/sqlalchemy/engine/create.py", line 590, in connect
    return dialect.connect(*cargs, **cparams)
  File "/usr/local/lib/python3.6/dist-packages/sqlalchemy/engine/default.py", line 597, in connect
    return self.dbapi.connect(*cargs, **cparams)
  File "/usr/local/lib/python3.6/dist-packages/psycopg2/__init__.py", line 122, in connect
    conn = _connect(dsn, connection_factory=connection_factory, **kwasync)
sqlalchemy.exc.OperationalError: (psycopg2.OperationalError) connection to server at "localhost" (::1), port 5432 failed: Connection refused
	Is the server running on that host and accepting TCP/IP connections?
connection to server at "localhost" (127.0.0.1), port 5432 failed: Connection refused
	Is the server running on that host and accepting TCP/IP connections?

(Background on this error at: https://sqlalche.me/e/14/e3q8)

During handling of the above exception, another exception occurred:

Traceback (most recent call last):
  File "/tmp/tmp.d9lusb0FGf/orchestra/orchestra/mailing/Postman.py", line 45, in __send
    server.login(self.__myEmail, self.__myPassword)
  File "/usr/lib/python3.6/smtplib.py", line 721, in login
    initial_response_ok=initial_response_ok)
  File "/usr/lib/python3.6/smtplib.py", line 631, in auth
    (code, resp) = self.docmd("AUTH", mechanism + " " + response)
  File "/usr/lib/python3.6/smtplib.py", line 421, in docmd
    return self.getreply()
  File "/usr/lib/python3.6/smtplib.py", line 394, in getreply
    raise SMTPServerDisconnected("Connection unexpectedly closed")
smtplib.SMTPServerDisconnected: Connection unexpectedly closed
Traceback (most recent call last):
  File "/usr/local/lib/python3.6/dist-packages/sqlalchemy/engine/base.py", line 3250, in _wrap_pool_connect
    return fn()
  File "/usr/local/lib/python3.6/dist-packages/sqlalchemy/pool/base.py", line 310, in connect
    return _ConnectionFairy._checkout(self)
  File "/usr/local/lib/python3.6/dist-packages/sqlalchemy/pool/base.py", line 868, in _checkout
    fairy = _ConnectionRecord.checkout(pool)
  File "/usr/local/lib/python3.6/dist-packages/sqlalchemy/pool/base.py", line 476, in checkout
    rec = pool._do_get()
  File "/usr/local/lib/python3.6/dist-packages/sqlalchemy/pool/impl.py", line 146, in _do_get
    self._dec_overflow()
  File "/usr/local/lib/python3.6/dist-packages/sqlalchemy/util/langhelpers.py", line 72, in __exit__
    with_traceback=exc_tb,
  File "/usr/local/lib/python3.6/dist-packages/sqlalchemy/util/compat.py", line 207, in raise_
    raise exception
  File "/usr/local/lib/python3.6/dist-packages/sqlalchemy/pool/impl.py", line 143, in _do_get
    return self._create_connection()
  File "/usr/local/lib/python3.6/dist-packages/sqlalchemy/pool/base.py", line 256, in _create_connection
    return _ConnectionRecord(self)
  File "/usr/local/lib/python3.6/dist-packages/sqlalchemy/pool/base.py", line 371, in __init__
    self.__connect()
  File "/usr/local/lib/python3.6/dist-packages/sqlalchemy/pool/base.py", line 666, in __connect
    pool.logger.debug("Error on connect(): %s", e)
  File "/usr/local/lib/python3.6/dist-packages/sqlalchemy/util/langhelpers.py", line 72, in __exit__
    with_traceback=exc_tb,
  File "/usr/local/lib/python3.6/dist-packages/sqlalchemy/util/compat.py", line 207, in raise_
    raise exception
  File "/usr/local/lib/python3.6/dist-packages/sqlalchemy/pool/base.py", line 661, in __connect
    self.dbapi_connection = connection = pool._invoke_creator(self)
  File "/usr/local/lib/python3.6/dist-packages/sqlalchemy/engine/create.py", line 590, in connect
    return dialect.connect(*cargs, **cparams)
  File "/usr/local/lib/python3.6/dist-packages/sqlalchemy/engine/default.py", line 597, in connect
    return self.dbapi.connect(*cargs, **cparams)
  File "/usr/local/lib/python3.6/dist-packages/psycopg2/__init__.py", line 122, in connect
    conn = _connect(dsn, connection_factory=connection_factory, **kwasync)
psycopg2.OperationalError: connection to server at "localhost" (::1), port 5432 failed: Connection refused
	Is the server running on that host and accepting TCP/IP connections?
connection to server at "localhost" (127.0.0.1), port 5432 failed: Connection refused
	Is the server running on that host and accepting TCP/IP connections?


The above exception was the direct cause of the following exception:

Traceback (most recent call last):
  File "/tmp/tmp.d9lusb0FGf/orchestra/orchestra/parsers/PilotParser.py", line 73, in run
    pilot.init()
  File "/tmp/tmp.d9lusb0FGf/orchestra/orchestra/Pilot.py", line 54, in init
    self.__devices.init()
  File "/tmp/tmp.d9lusb0FGf/orchestra/orchestra/core/Devices.py", line 34, in init
    for device in self.__db.session().query(Device).filter(Device.nodename==self.nodename).all():
  File "/usr/local/lib/python3.6/dist-packages/sqlalchemy/orm/query.py", line 2759, in all
    return self._iter().all()
  File "/usr/local/lib/python3.6/dist-packages/sqlalchemy/orm/query.py", line 2897, in _iter
    execution_options={"_sa_orm_load_options": self.load_options},
  File "/usr/local/lib/python3.6/dist-packages/sqlalchemy/orm/session.py", line 1691, in execute
    conn = self._connection_for_bind(bind)
  File "/usr/local/lib/python3.6/dist-packages/sqlalchemy/orm/session.py", line 1533, in _connection_for_bind
    engine, execution_options
  File "/usr/local/lib/python3.6/dist-packages/sqlalchemy/orm/session.py", line 747, in _connection_for_bind
    conn = bind.connect()
  File "/usr/local/lib/python3.6/dist-packages/sqlalchemy/engine/base.py", line 3204, in connect
    return self._connection_cls(self, close_with_result=close_with_result)
  File "/usr/local/lib/python3.6/dist-packages/sqlalchemy/engine/base.py", line 96, in __init__
    else engine.raw_connection()
  File "/usr/local/lib/python3.6/dist-packages/sqlalchemy/engine/base.py", line 3283, in raw_connection
    return self._wrap_pool_connect(self.pool.connect, _connection)
  File "/usr/local/lib/python3.6/dist-packages/sqlalchemy/engine/base.py", line 3254, in _wrap_pool_connect
    e, dialect, self
  File "/usr/local/lib/python3.6/dist-packages/sqlalchemy/engine/base.py", line 2101, in _handle_dbapi_exception_noconnection
    sqlalchemy_exception, with_traceback=exc_info[2], from_=e
  File "/usr/local/lib/python3.6/dist-packages/sqlalchemy/util/compat.py", line 207, in raise_
    raise exception
  File "/usr/local/lib/python3.6/dist-packages/sqlalchemy/engine/base.py", line 3250, in _wrap_pool_connect
    return fn()
  File "/usr/local/lib/python3.6/dist-packages/sqlalchemy/pool/base.py", line 310, in connect
    return _ConnectionFairy._checkout(self)
  File "/usr/local/lib/python3.6/dist-packages/sqlalchemy/pool/base.py", line 868, in _checkout
    fairy = _ConnectionRecord.checkout(pool)
  File "/usr/local/lib/python3.6/dist-packages/sqlalchemy/pool/base.py", line 476, in checkout
    rec = pool._do_get()
  File "/usr/local/lib/python3.6/dist-packages/sqlalchemy/pool/impl.py", line 146, in _do_get
    self._dec_overflow()
  File "/usr/local/lib/python3.6/dist-packages/sqlalchemy/util/langhelpers.py", line 72, in __exit__
    with_traceback=exc_tb,
  File "/usr/local/lib/python3.6/dist-packages/sqlalchemy/util/compat.py", line 207, in raise_
    raise exception
  File "/usr/local/lib/python3.6/dist-packages/sqlalchemy/pool/impl.py", line 143, in _do_get
    return self._create_connection()
  File "/usr/local/lib/python3.6/dist-packages/sqlalchemy/pool/base.py", line 256, in _create_connection
    return _ConnectionRecord(self)
  File "/usr/local/lib/python3.6/dist-packages/sqlalchemy/pool/base.py", line 371, in __init__
    self.__connect()
  File "/usr/local/lib/python3.6/dist-packages/sqlalchemy/pool/base.py", line 666, in __connect
    pool.logger.debug("Error on connect(): %s", e)
  File "/usr/local/lib/python3.6/dist-packages/sqlalchemy/util/langhelpers.py", line 72, in __exit__
    with_traceback=exc_tb,
  File "/usr/local/lib/python3.6/dist-packages/sqlalchemy/util/compat.py", line 207, in raise_
    raise exception
  File "/usr/local/lib/python3.6/dist-packages/sqlalchemy/pool/base.py", line 661, in __connect
    self.dbapi_connection = connection = pool._invoke_creator(self)
  File "/usr/local/lib/python3.6/dist-packages/sqlalchemy/engine/create.py", line 590, in connect
    return dialect.connect(*cargs, **cparams)
  File "/usr/local/lib/python3.6/dist-packages/sqlalchemy/engine/default.py", line 597, in connect
    return self.dbapi.connect(*cargs, **cparams)
  File "/usr/local/lib/python3.6/dist-packages/psycopg2/__init__.py", line 122, in connect
    conn = _connect(dsn, connection_factory=connection_factory, **kwasync)
sqlalchemy.exc.OperationalError: (psycopg2.OperationalError) connection to server at "localhost" (::1), port 5432 failed: Connection refused
	Is the server running on that host and accepting TCP/IP connections?
connection to server at "localhost" (127.0.0.1), port 5432 failed: Connection refused
	Is the server running on that host and accepting TCP/IP connections?

(Background on this error at: https://sqlalche.me/e/14/e3q8)

